Workbook

Sheet RESUMO
A1: FORNO | B1: HORAS CALENDARIO | C1: PARADAS PROGRAMADAS (H) | D1: PARADAS NÃO PROGRAMADAS (H) | E1: Observação
A2: 01 | B2: =30*24 -> 720 | C2: ='Forno 01'!H69 -> 3.2618056 | D2: ='Forno 01'!I69 -> 1.0861111 | E2: Para o forno 08 não foi considerado os primeiros 5 dias de abril/2023
A3: 03 | B3: =30*24 -> 720 | C3: ='Forno 03'!H69 -> 2.5513889 | D3: ='Forno 03'!I69 -> 1.1277778
A4: 05 | B4: =30*24 -> 720 | C4: ='Forno 05'!H53 -> 2.1055556 | D4: ='Forno 05'!I53 -> 0.74305556
A5: 06 | B5: =30*24 -> 720 | C5: ='Forno 06'!H61 -> 1.9555556 | D5: ='Forno 06'!I61 -> 0.56597222
A6: 08 | B6: =30*24-5*24 -> 600 | C6: ='Forno 08'!H140 -> 1.3611111 | D6: ='Forno 08'!I140 -> 3.8798611
A7: TOTAL (H) | B7: =SUM(B2:B6) -> 3480 | C7: =SUM(C2:C6)*24 -> 269.65 | D7: =SUM(D2:D6)*24 -> 177.66667
B8: (%) | C8: =C7/B7 -> 0.077485632 | D8: =D7/(B7-C7) -> 0.055341837
B9: IF(%) | C9: =(1-C8)*(1-D8) -> 0.87146073
C10: =TEXT(C7,"")
A12: 04 | B12: =30*24 -> 720 | C12: ='Forno 04 07'!I483 -> 71.716667 | D12: ='Forno 04 07'!J483 -> 117.88333
A13: 07 | B13: =30*24 -> 720
A14: TOTAL (H) | B14: =SUM(B12:B13) -> 1440 | C14: =SUM(C12:C13) -> 71.716667 | D14: =SUM(D12:D13) -> 117.88333
B15: (%) | C15: =C14/B14 -> 0.049803241 | D15: =D14/(B14-C14) -> 0.086154183
B16: IF(%) | C16: =(1-C15)*(1-D15) -> 0.86833333
A18: 09 | B18: =30*24 -> 720 | C18: ='Forno 09'!H79 -> 2.2732639 | D18: ='Forno 09'!I79 -> 1.1479167
A19: 10 | B19: =30*24 -> 720 | C19: ='Forno 10 a 14'!H359 -> 10.261806 | D19: ='Forno 10 a 14'!I359 -> 7.7868056
A20: 11 | B20: =30*24 -> 720
A21: 12 | B21: =30*24 -> 720
A22: 13 | B22: =30*24 -> 720
A23: 14 | B23: =30*24 -> 720
A24: TOTAL (H) | B24: =SUM(B18:B23) -> 4320 | C24: =SUM(C18:C23)*24 -> 300.84167 | D24: =SUM(D18:D23)*24 -> 214.43333
B25: (%) | C25: =C24/B24 -> 0.069639275 | D25: =D24/(B24-C24) -> 0.053352796
B26: IF(%) | C26: =(1-C25)*(1-D25) -> 0.88072338
A32: CÁLCULO DAS PARADAS PROGRAMADAS CONSIDERANDO AS PARADAS PROGRAMADAS DO FORNOS PARA MANUTENÇÃO
A33: Fornos | B33: Ano/Mês | C33: Dias Mês | D33: Qtde Fornos | E33: Dias Parada | F33: Horas Parada | G33: Horas Mês | H33: % Paradas Programadas | I33: Horas Paradas Programadas | J33: Total Horas Paradas | K33: % Paradas Programadas Ajustada
A34: Forno 01 08 | B34: 2023/06 | C34: 30 | D34: 2 | E34: 10 | F34: =E34*24 -> 240 | G34: =C34*D34*24 -> 1440 | H34: =C8 -> 0.077485632 | I34: =(G34-F34) * H34 -> 92.982759 | J34: =I34+F34 -> 332.98276 | K34: =J34/G34 -> 0.23123803
A35: Forno 03 | B35: 2023/07 | C35: 31 | D35: 1 | E35: 3 | F35: =E35*24 -> 72 | G35: =C35*D35*24 -> 744 | H35: =H34 -> 0.077485632 | I35: =(G35-F35) * H35 -> 52.070345 | J35: =I35+F35 -> 124.07034 | K35: =J35/G35 -> 0.16676122
A36: Forno 04 07 | B36: 2023/05 | C36: 31 | D36: 2 | E36: 20 | F36: =E36*24 -> 480 | G36: =C36*D36*24 -> 1488 | H36: =C15 -> 0.049803241 | I36: =(G36-F36) * H36 -> 50.201667 | J36: =I36+F36 -> 530.20167 | K36: =J36/G36 -> 0.35631832
B37: 2023/08 | C37: 31 | D37: 2 | E37: 20 | F37: =E37*24 -> 480 | G37: =C37*D37*24 -> 1488 | H37: =H36 -> 0.049803241 | I37: =(G37-F37) * H37 -> 50.201667 | J37: =I37+F37 -> 530.20167 | K37: =J37/G37 -> 0.35631832
A38: Forno 05 06 | B38: 2023/08 | C38: 31 | D38: 2 | E38: 17 | F38: =E38*24 -> 408 | G38: =C38*D38*24 -> 1488 | H38: =H34 -> 0.077485632 | I38: =(G38-F38) * H38 -> 83.684483 | J38: =I38+F38 -> 491.68448 | K38: =J38/G38 -> 0.33043312
B39: 2023/09 | C39: 30 | D39: 2 | E39: 17 | F39: =E39*24 -> 408 | G39: =C39*D39*24 -> 1440 | H39: =H38 -> 0.077485632 | I39: =(G39-F39) * H39 -> 79.965172 | J39: =I39+F39 -> 487.96517 | K39: =J39/G39 -> 0.3388647
A40: Forno 09 | B40: NÃO TEREMOS PARADA PARA MANUTENÇÃO NESSE FORNO NO PERIODO DE MAIO A DEZEMBRO 2023
A41: Forno 10 14 | B41: 2023/10 | C41: 31 | D41: 5 | E41: 17 | F41: =E41*24 -> 408 | G41: =C41*D41*24 -> 3720 | H41: =C25 -> 0.069639275 | I41: =(G41-F41) * H41 -> 230.64528 | J41: =I41+F41 -> 638.64528 | K41: =J41/G41 -> 0.17167884
B42: 2023/11 | C42: 30 | D42: 5 | E42: 17 | F42: =E42*24 -> 408 | G42: =C42*D42*24 -> 3600 | H42: =H41 -> 0.069639275 | I42: =(G42-F42) * H42 -> 222.28856 | J42: =I42+F42 -> 630.28856 | K42: =J42/G42 -> 0.17508016

Sheet Forno 01
A1: Forno | B1: Dia | C1: H Inicial | D1: H Final | E1: Duração | F1: Motivo | G1: TIPO | H1: TIPO P | I1: TIPO NP
A2: FN01 | B2: 45019 | C2: 0.74861111 | D2: 0.8125 | E2: 0.063888889 | F2: 11 - Modulação | G2: =VLOOKUP(F2,'Tipo Parada Fab 1'!$A$2:$B$27,2,FALSE()) -> P | H2: =IF(G2="P",E2,"") -> 0.063888889 | I2: =IF(G2="NP",E2,"")
A3: FN01 | B3: 45019 | C3: 0.8125 | D3: 0.87569444 | E3: 0.063194444 | F3: 11 - Modulação | G3: =VLOOKUP(F3,'Tipo Parada Fab 1'!$A$2:$B$27,2,FALSE()) -> P | H3: =IF(G3="P",E3,"") -> 0.063194444 | I3: =IF(G3="NP",E3,"")
A4: FN01 | B4: 45020 | C4: 0.74861111 | D4: 0.8125 | E4: 0.063888889 | F4: 11 - Modulação | G4: =VLOOKUP(F4,'Tipo Parada Fab 1'!$A$2:$B$27,2,FALSE()) -> P | H4: =IF(G4="P",E4,"") -> 0.063888889 | I4: =IF(G4="NP",E4,"")
A5: FN01 | B5: 45020 | C5: 0.8125 | D5: 0.875 | E5: 0.0625 | F5: 11 - Modulação | G5: =VLOOKUP(F5,'Tipo Parada Fab 1'!$A$2:$B$27,2,FALSE()) -> P | H5: =IF(G5="P",E5,"") -> 0.0625 | I5: =IF(G5="NP",E5,"")
A6: FN01 | B6: 45020 | C6: 0.875 | D6: 0.99305556 | E6: 0.11805556 | F6: 22 - Recuperação de testa | G6: =VLOOKUP(F6,'Tipo Parada Fab 1'!$A$2:$B$27,2,FALSE()) -> P | H6: =IF(G6="P",E6,"") -> 0.11805556 | I6: =IF(G6="NP",E6,"")
A7: FN01 | B7: 45020 | C7: 0.99305556 | D7: 0.0034722222 | E7: 0.010416667 | F7: 12 - Outros Mecânica | G7: =VLOOKUP(F7,'Tipo Parada Fab 1'!$A$2:$B$27,2,FALSE()) -> NP | H7: =IF(G7="P",E7,"") | I7: =IF(G7="NP",E7,"") -> 0.010416667
A8: FN01 | B8: 45021 | C8: 0.74861111 | D8: 0.8125 | E8: 0.063888889 | F8: 11 - Modulação | G8: =VLOOKUP(F8,'Tipo Parada Fab 1'!$A$2:$B$27,2,FALSE()) -> P | H8: =IF(G8="P",E8,"") -> 0.063888889 | I8: =IF(G8="NP",E8,"")
A9: FN01 | B9: 45021 | C9: 0.8125 | D9: 0.87569444 | E9: 0.063194444 | F9: 11 - Modulação | G9: =VLOOKUP(F9,'Tipo Parada Fab 1'!$A$2:$B$27,2,FALSE()) -> P | H9: =IF(G9="P",E9,"") -> 0.063194444 | I9: =IF(G9="NP",E9,"")
A10: FN01 | B10: 45022 | C10: 0.74861111 | D10: 0.8125 | E10: 0.063888889 | F10: 11 - Modulação | G10: =VLOOKUP(F10,'Tipo Parada Fab 1'!$A$2:$B$27,2,FALSE()) -> P | H10: =IF(G10="P",E10,"") -> 0.063888889 | I10: =IF(G10="NP",E10,"")
A11: FN01 | B11: 45022 | C11: 0.8125 | D11: 0.87569444 | E11: 0.063194444 | F11: 11 - Modulação | G11: =VLOOKUP(F11,'Tipo Parada Fab 1'!$A$2:$B$27,2,FALSE()) -> P | H11: =IF(G11="P",E11,"") -> 0.063194444 | I11: =IF(G11="NP",E11,"")
A12: FN01 | B12: 45022 | C12: 0.89166667 | D12: 0.89305556 | E12: 0.0013888889 | F12: 13 - Outros Produção | G12: =VLOOKUP(F12,'Tipo Parada Fab 1'!$A$2:$B$27,2,FALSE()) -> NP | H12: =IF(G12="P",E12,"") | I12: =IF(G12="NP",E12,"") -> 0.0013888889
A13: FN01 | B13: 45023 | C13: 0.64791667 | D13: 0.67569444 | E13: 0.027777778 | F13: 16 - Problema no Transformador | G13: =VLOOKUP(F13,'Tipo Parada Fab 1'!$A$2:$B$27,2,FALSE()) -> NP | H13: =IF(G13="P",E13,"") | I13: =IF(G13="NP",E13,"") -> 0.027777778
... A68: FN01 | B68: 45046 | C68: 0.75833333 | D68: 0.8125 | E68: 0.054166667 | F68: 31 - Vazamento de água, outros | G68: =VLOOKUP(F68,'Tipo Parada Fab 1'!$A$2:$B$27,2,FALSE()) -> NP | H68: =IF(G68="P",E68,"") | I68: =IF(G68="NP",E68,"") -> 0.054166667
E69: =SUM(E2:E68) -> 4.3479167 | H69: =SUM(H2:H68) -> 3.2618056 | I69: =SUM(I2:I68) -> 1.0861111

Sheet Forno 03
A1: Forno | B1: Dia | C1: H Inicial | D1: H Final | E1: Duração | F1: Motivo | G1: TIPO | H1: TIPO P | I1: TIPO NP
A2: FN03 | B2: 45019 | C2: 0.74861111 | D2: 0.8125 | E2: 0.063888889 | F2: 11 - Modulação | G2: =VLOOKUP(F2,'Tipo Parada Fab 1'!$A$2:$B$27,2,FALSE()) -> P | H2: =IF(G2="P",E2,"") -> 0.063888889 | I2: =IF(G2="NP",E2,"")
A3: FN03 | B3: 45019 | C3: 0.8125 | D3: 0.87569444 | E3: 0.063194444 | F3: 11 - Modulação | G3: =VLOOKUP(F3,'Tipo Parada Fab 1'!$A$2:$B$27,2,FALSE()) -> P | H3: =IF(G3="P",E3,"") -> 0.063194444 | I3: =IF(G3="NP",E3,"")
A4: FN03 | B4: 45020 | C4: 0.74861111 | D4: 0.8125 | E4: 0.063888889 | F4: 11 - Modulação | G4: =VLOOKUP(F4,'Tipo Parada Fab 1'!$A$2:$B$27,2,FALSE()) -> P | H4: =IF(G4="P",E4,"") -> 0.063888889 | I4: =IF(G4="NP",E4,"")
A5: FN03 | B5: 45020 | C5: 0.8125 | D5: 0.875 | E5: 0.0625 | F5: 11 - Modulação | G5: =VLOOKUP(F5,'Tipo Parada Fab 1'!$A$2:$B$27,2,FALSE()) -> P | H5: =IF(G5="P",E5,"") -> 0.0625 | I5: =IF(G5="NP",E5,"")
A6: FN03 | B6: 45020 | C6: 0.875 | D6: 0.87986111 | E6: 0.0048611111 | F6: 14 - Problema Elétrico | G6: =VLOOKUP(F6,'Tipo Parada Fab 1'!$A$2:$B$27,2,FALSE()) -> NP | H6: =IF(G6="P",E6,"") | I6: =IF(G6="NP",E6,"") -> 0.0048611111
A7: FN03 | B7: 45021 | C7: 0.74861111 | D7: 0.8125 | E7: 0.063888889 | F7: 11 - Modulação | G7: =VLOOKUP(F7,'Tipo Parada Fab 1'!$A$2:$B$27,2,FALSE()) -> P | H7: =IF(G7="P",E7,"") -> 0.063888889 | I7: =IF(G7="NP",E7,"")
A8: FN03 | B8: 45021 | C8: 0.8125 | D8: 0.87569444 | E8: 0.063194444 | F8: 11 - Modulação | G8: =VLOOKUP(F8,'Tipo Parada Fab 1'!$A$2:$B$27,2,FALSE()) -> P | H8: =IF(G8="P",E8,"") -> 0.063194444 | I8: =IF(G8="NP",E8,"")
A9: FN03 | B9: 45022 | C9: 0.74861111 | D9: 0.8125 | E9: 0.063888889 | F9: 11 - Modulação | G9: =VLOOKUP(F9,'Tipo Parada Fab 1'!$A$2:$B$27,2,FALSE()) -> P | H9: =IF(G9="P",E9,"") -> 0.063888889 | I9: =IF(G9="NP",E9,"")
A10: FN03 | B10: 45022 | C10: 0.8125 | D10: 0.87569444 | E10: 0.063194444 | F10: 11 - Modulação | G10: =VLOOKUP(F10,'Tipo Parada Fab 1'!$A$2:$B$27,2,FALSE()) -> P | H10: =IF(G10="P",E10,"") -> 0.063194444 | I10: =IF(G10="NP",E10,"")
A11: FN03 | B11: 45023 | C11: 0.075694444 | D11: 0.085416667 | E11: 0.0097222222 | F11: 26 - Tamponar forno | G11: =VLOOKUP(F11,'Tipo Parada Fab 1'!$A$2:$B$27,2,FALSE()) -> NP | H11: =IF(G11="P",E11,"") | I11: =IF(G11="NP",E11,"") -> 0.0097222222
A12: FN03 | B12: 45023 | C12: 0.22777778 | D12: 0.3125 | E12: 0.084722222 | F12: 24 - Soprar tubulação de água / Água fervendo | G12: =VLOOKUP(F12,'Tipo Parada Fab 1'!$A$2:$B$27,2,FALSE()) -> NP | H12: =IF(G12="P",E12,"") | I12: =IF(G12="NP",E12,"") -> 0.084722222
A13: FN03 | B13: 45023 | C13: 0.3125 | D13: 0.5625 | E13: 0.25 | F13: 24 - Soprar tubulação de água / Água fervendo | G13: =VLOOKUP(F13,'Tipo Parada Fab 1'!$A$2:$B$27,2,FALSE()) -> NP | H13: =IF(G13="P",E13,"") | I13: =IF(G13="NP",E13,"") -> 0.25
... A68: FN03 | B68: 45044 | C68: 0.87569444 | D68: 0.94027778 | E68: 0.064583333 | F68: 22 - Recuperação de testa | G68: =VLOOKUP(F68,'Tipo Parada Fab 1'!$A$2:$B$27,2,FALSE()) -> P | H68: =IF(G68="P",E68,"") -> 0.064583333 | I68: =IF(G68="NP",E68,"")
E69: =SUM(E2:E68) -> 3.6791667 | H69: =SUM(H2:H68) -> 2.5513889 | I69: =SUM(I2:I68) -> 1.1277778
H72: =IF(G72="P",E72,"") | I72: =IF(G72="NP",E72,"")

Sheet Forno 05
A1: Forno | B1: Dia | C1: H Inicial | D1: H Final | E1: Duração | F1: Motivo | G1: TIPO | H1: TIPO P | I1: TIPO NP
A2: FN05 | B2: 45017 | C2: 0.0625 | D2: 0.21041667 | E2: 0.14791667 | F2: 28 - Vazamento de água em flexíveis | G2: =VLOOKUP(F2,'Tipo Parada Fab 1'!$A$2:$B$27,2,FALSE()) -> NP | H2: =IF(G2="P",E2,"") | I2: =IF(G2="NP",E2,"") -> 0.14791667
A3: FN05 | B3: 45017 | C3: 0.57777778 | D3: 0.5875 | E3: 0.0097222222 | F3: 13 - Outros Produção | G3: =VLOOKUP(F3,'Tipo Parada Fab 1'!$A$2:$B$27,2,FALSE()) -> NP | H3: =IF(G3="P",E3,"") | I3: =IF(G3="NP",E3,"") -> 0.0097222222
A4: FN05 | B4: 45018 | C4: 0.12361111 | D4: 0.21666667 | E4: 0.093055556 | F4: 2 - Cortar fita, substituir flexível | G4: =VLOOKUP(F4,'Tipo Parada Fab 1'!$A$2:$B$27,2,FALSE()) -> NP | H4: =IF(G4="P",E4,"") | I4: =IF(G4="NP",E4,"") -> 0.093055556
A5: FN05 | B5: 45019 | C5: 0.63194444 | D5: 0.8125 | E5: 0.18055556 | F5: 28 - Vazamento de água em flexíveis | G5: =VLOOKUP(F5,'Tipo Parada Fab 1'!$A$2:$B$27,2,FALSE()) -> NP | H5: =IF(G5="P",E5,"") | I5: =IF(G5="NP",E5,"") -> 0.18055556
A6: FN05 | B6: 45019 | C6: 0.8125 | D6: 0.87569444 | E6: 0.063194444 | F6: 11 - Modulação | G6: =VLOOKUP(F6,'Tipo Parada Fab 1'!$A$2:$B$27,2,FALSE()) -> P | H6: =IF(G6="P",E6,"") -> 0.063194444 | I6: =IF(G6="NP",E6,"")
A7: FN05 | B7: 45020 | C7: 0.62152778 | D7: 0.62430556 | E7: 0.0027777778 | F7: 23 - Sobrecarga | G7: =VLOOKUP(F7,'Tipo Parada Fab 1'!$A$2:$B$27,2,FALSE()) -> NP | H7: =IF(G7="P",E7,"") | I7: =IF(G7="NP",E7,"") -> 0.0027777778
A8: FN05 | B8: 45020 | C8: 0.74861111 | D8: 0.8125 | E8: 0.063888889 | F8: 11 - Modulação | G8: =VLOOKUP(F8,'Tipo Parada Fab 1'!$A$2:$B$27,2,FALSE()) -> P | H8: =IF(G8="P",E8,"") -> 0.063888889 | I8: =IF(G8="NP",E8,"")
A9: FN05 | B9: 45020 | C9: 0.8125 | D9: 0.87569444 | E9: 0.063194444 | F9: 11 - Modulação | G9: =VLOOKUP(F9,'Tipo Parada Fab 1'!$A$2:$B$27,2,FALSE()) -> P | H9: =IF(G9="P",E9,"") -> 0.063194444 | I9: =IF(G9="NP",E9,"")
A10: FN05 | B10: 45021 | C10: 0.74861111 | D10: 0.8125 | E10: 0.063888889 | F10: 11 - Modulação | G10: =VLOOKUP(F10,'Tipo Parada Fab 1'!$A$2:$B$27,2,FALSE()) -> P | H10: =IF(G10="P",E10,"") -> 0.063888889 | I10: =IF(G10="NP",E10,"")
A11: FN05 | B11: 45021 | C11: 0.8125 | D11: 0.87569444 | E11: 0.063194444 | F11: 11 - Modulação | G11: =VLOOKUP(F11,'Tipo Parada Fab 1'!$A$2:$B$27,2,FALSE()) -> P | H11: =IF(G11="P",E11,"") -> 0.063194444 | I11: =IF(G11="NP",E11,"")
A12: FN05 | B12: 45022 | C12: 0.74861111 | D12: 0.8125 | E12: 0.063888889 | F12: 11 - Modulação | G12: =VLOOKUP(F12,'Tipo Parada Fab 1'!$A$2:$B$27,2,FALSE()) -> P | H12: =IF(G12="P",E12,"") -> 0.063888889 | I12: =IF(G12="NP",E12,"")
A13: FN05 | B13: 45022 | C13: 0.8125 | D13: 0.87569444 | E13: 0.063194444 | F13: 11 - Modulação | G13: =VLOOKUP(F13,'Tipo Parada Fab 1'!$A$2:$B$27,2,FALSE()) -> P | H13: =IF(G13="P",E13,"") -> 0.063194444 | I13: =IF(G13="NP",E13,"")
... A52: FN05 | B52: 45044 | C52: 0.8125 | D52: 0.87569444 | E52: 0.063194444 | F52: 11 - Modulação | G52: =VLOOKUP(F52,'Tipo Parada Fab 1'!$A$2:$B$27,2,FALSE()) -> P | H52: =IF(G52="P",E52,"") -> 0.063194444 | I52: =IF(G52="NP",E52,"")
E53: =SUM(E2:E52) -> 2.8486111 | H53: =SUM(H2:H52) -> 2.1055556 | I53: =SUM(I2:I52) -> 0.74305556

Sheet Forno 06
A1: Forno | B1: Dia | C1: H Inicial | D1: H Final | E1: Duração | F1: Motivo | G1: TIPO | H1: TIPO P | I1: TIPO NP
A2: FN06 | B2: 45018 | C2: 0.52222222 | D2: 0.52777778 | E2: 0.0055555556 | F2: 23 - Sobrecarga | G2: =VLOOKUP(F2,'Tipo Parada Fab 1'!$A$2:$B$27,2,FALSE()) -> NP | H2: =IF(G2="P",E2,"") | I2: =IF(G2="NP",E2,"") -> 0.0055555556
A3: FN06 | B3: 45019 | C3: 0.64375 | D3: 0.64722222 | E3: 0.0034722222 | F3: 13 - Outros Produção | G3: =VLOOKUP(F3,'Tipo Parada Fab 1'!$A$2:$B$27,2,FALSE()) -> NP | H3: =IF(G3="P",E3,"") | I3: =IF(G3="NP",E3,"") -> 0.0034722222
A4: FN06 | B4: 45019 | C4: 0.65208333 | D4: 0.6625 | E4: 0.010416667 | F4: 13 - Outros Produção | G4: =VLOOKUP(F4,'Tipo Parada Fab 1'!$A$2:$B$27,2,FALSE()) -> NP | H4: =IF(G4="P",E4,"") | I4: =IF(G4="NP",E4,"") -> 0.010416667
A5: FN06 | B5: 45019 | C5: 0.8125 | D5: 0.87569444 | E5: 0.063194444 | F5: 11 - Modulação | G5: =VLOOKUP(F5,'Tipo Parada Fab 1'!$A$2:$B$27,2,FALSE()) -> P | H5: =IF(G5="P",E5,"") -> 0.063194444 | I5: =IF(G5="NP",E5,"")
A6: FN06 | B6: 45019 | C6: 0.93611111 | D6: 0.9375 | E6: 0.0013888889 | F6: 25 - Sopro / Fervura | G6: =VLOOKUP(F6,'Tipo Parada Fab 1'!$A$2:$B$27,2,FALSE()) -> NP | H6: =IF(G6="P",E6,"") | I6: =IF(G6="NP",E6,"") -> 0.0013888889
A7: FN06 | B7: 45019 | C7: 0.95902778 | D7: 0.96319444 | E7: 0.0041666667 | F7: 13 - Outros Produção | G7: =VLOOKUP(F7,'Tipo Parada Fab 1'!$A$2:$B$27,2,FALSE()) -> NP | H7: =IF(G7="P",E7,"") | I7: =IF(G7="NP",E7,"") -> 0.0041666667
A8: FN06 | B8: 45020 | C8: 0.74861111 | D8: 0.8125 | E8: 0.063888889 | F8: 11 - Modulação | G8: =VLOOKUP(F8,'Tipo Parada Fab 1'!$A$2:$B$27,2,FALSE()) -> P | H8: =IF(G8="P",E8,"") -> 0.063888889 | I8: =IF(G8="NP",E8,"")
A9: FN06 | B9: 45020 | C9: 0.8125 | D9: 0.85069444 | E9: 0.038194444 | F9: 11 - Modulação | G9: =VLOOKUP(F9,'Tipo Parada Fab 1'!$A$2:$B$27,2,FALSE()) -> P | H9: =IF(G9="P",E9,"") -> 0.038194444 | I9: =IF(G9="NP",E9,"")
A10: FN06 | B10: 45021 | C10: 0.74861111 | D10: 0.8125 | E10: 0.063888889 | F10: 11 - Modulação | G10: =VLOOKUP(F10,'Tipo Parada Fab 1'!$A$2:$B$27,2,FALSE()) -> P | H10: =IF(G10="P",E10,"") -> 0.063888889 | I10: =IF(G10="NP",E10,"")
A11: FN06 | B11: 45021 | C11: 0.8125 | D11: 0.875 | E11: 0.0625 | F11: 11 - Modulação | G11: =VLOOKUP(F11,'Tipo Parada Fab 1'!$A$2:$B$27,2,FALSE()) -> P | H11: =IF(G11="P",E11,"") -> 0.0625 | I11: =IF(G11="NP",E11,"")
A12: FN06 | B12: 45021 | C12: 0.875 | D12: 0.95625 | E12: 0.08125 | F12: 29 - Vazamento de água na coroa | G12: =VLOOKUP(F12,'Tipo Parada Fab 1'!$A$2:$B$27,2,FALSE()) -> NP | H12: =IF(G12="P",E12,"") | I12: =IF(G12="NP",E12,"") -> 0.08125
A13: FN06 | B13: 45022 | C13: 0.80069444 | D13: 0.80555556 | E13: 0.0048611111 | F13: 26 - Tamponar forno | G13: =VLOOKUP(F13,'Tipo Parada Fab 1'!$A$2:$B$27,2,FALSE()) -> NP | H13: =IF(G13="P",E13,"") | I13: =IF(G13="NP",E13,"") -> 0.0048611111
... A60: FN06 | B60: 45044 | C60: 0.8125 | D60: 0.87569444 | E60: 0.063194444 | F60: 11 - Modulação | G60: =VLOOKUP(F60,'Tipo Parada Fab 1'!$A$2:$B$27,2,FALSE()) -> P | H60: =IF(G60="P",E60,"") -> 0.063194444 | I60: =IF(G60="NP",E60,"")
E61: =SUM(E2:E60) -> 2.5215278 | H61: =SUM(H2:H60) -> 1.9555556 | I61: =SUM(I2:I60) -> 0.56597222

Sheet Forno 08
A1: Forno | B1: Dia | C1: H Inicial | D1: H Final | E1: Duração | F1: Motivo | G1: TIPO | H1: TIPO P | I1: TIPO NP
A2: FN08 | B2: 45017 | C2: 0.16666667 | D2: 0.17986111 | E2: 0.013194444 | F2: 10 - Medição de eletrodos | G2: =VLOOKUP(F2,'Tipo Parada Fab 1'!$A$2:$B$27,2,FALSE()) -> NP | H2: =IF(G2="P",E2,"")
A3: FN08 | B3: 45017 | C3: 0.36944444 | D3: 0.49097222 | E3: 0.12152778 | F3: 13 - Outros Produção | G3: =VLOOKUP(F3,'Tipo Parada Fab 1'!$A$2:$B$27,2,FALSE()) -> NP | H3: =IF(G3="P",E3,"")
A4: FN08 | B4: 45017 | C4: 0.66597222 | D4: 0.73194444 | E4: 0.065972222 | F4: 13 - Outros Produção | G4: =VLOOKUP(F4,'Tipo Parada Fab 1'!$A$2:$B$27,2,FALSE()) -> NP | H4: =IF(G4="P",E4,"")
A5: FN08 | B5: 45017 | C5: 0.73194444 | D5: 0.7375 | E5: 0.0055555556 | F5: 10 - Medição de eletrodos | G5: =VLOOKUP(F5,'Tipo Parada Fab 1'!$A$2:$B$27,2,FALSE()) -> NP | H5: =IF(G5="P",E5,"")
A6: FN08 | B6: 45018 | C6: 0.21736111 | D6: 0.24166667 | E6: 0.024305556 | F6: 10 - Medição de eletrodos | G6: =VLOOKUP(F6,'Tipo Parada Fab 1'!$A$2:$B$27,2,FALSE()) -> NP | H6: =IF(G6="P",E6,"")
A7: FN08 | B7: 45018 | C7: 0.46527778 | D7: 0.5625 | E7: 0.097222222 | F7: 13 - Outros Produção | G7: =VLOOKUP(F7,'Tipo Parada Fab 1'!$A$2:$B$27,2,FALSE()) -> NP | H7: =IF(G7="P",E7,"")
A8: FN08 | B8: 45018 | C8: 0.5625 | D8: 0.56458333 | E8: 0.0020833333 | F8: 13 - Outros Produção | G8: =VLOOKUP(F8,'Tipo Parada Fab 1'!$A$2:$B$27,2,FALSE()) -> NP | H8: =IF(G8="P",E8,"")
A9: FN08 | B9: 45018 | C9: 0.57638889 | D9: 0.57847222 | E9: 0.0020833333 | F9: 9 - Inspeção | G9: =VLOOKUP(F9,'Tipo Parada Fab 1'!$A$2:$B$27,2,FALSE()) -> NP | H9: =IF(G9="P",E9,"")
A10: FN08 | B10: 45018 | C10: 0.73819444 | D10: 0.74097222 | E10: 0.0027777778 | F10: 13 - Outros Produção | G10: =VLOOKUP(F10,'Tipo Parada Fab 1'!$A$2:$B$27,2,FALSE()) -> NP | H10: =IF(G10="P",E10,"")
A11: FN08 | B11: 45018 | C11: 0.78263889 | D11: 0.8125 | E11: 0.029861111 | F11: 13 - Outros Produção | G11: =VLOOKUP(F11,'Tipo Parada Fab 1'!$A$2:$B$27,2,FALSE()) -> NP | H11: =IF(G11="P",E11,"")
A12: FN08 | B12: 45018 | C12: 0.8125 | D12: 0.82083333 | E12: 0.0083333333 | F12: 13 - Outros Produção | G12: =VLOOKUP(F12,'Tipo Parada Fab 1'!$A$2:$B$27,2,FALSE()) -> NP | H12: =IF(G12="P",E12,"")
A13: FN08 | B13: 45018 | C13: 0.82152778 | D13: 0.82361111 | E13: 0.0020833333 | F13: 13 - Outros Produção | G13: =VLOOKUP(F13,'Tipo Parada Fab 1'!$A$2:$B$27,2,FALSE()) -> NP | H13: =IF(G13="P",E13,"")
... A23: FN08 | B23: 45021 | C23: 0.87430556 | D23: 0.88888889 | E23: 0.014583333 | F23: 13 - Outros Produção | G23: =VLOOKUP(F23,'Tipo Parada Fab 1'!$A$2:$B$27,2,FALSE()) -> NP | H23: =IF(G23="P",E23,"")
A24: FN08 | B24: 45022 | C24: 0.0625 | D24: 0.20208333 | E24: 0.13958333 | F24: 14 - Problema Elétrico | G24: =VLOOKUP(F24,'Tipo Parada Fab 1'!$A$2:$B$27,2,FALSE()) -> NP | H24: =IF(G24="P",E24,"") | I24: =IF(G24="NP",E24,"") -> 0.13958333
A25: FN08 | B25: 45022 | C25: 0.20069444 | D25: 0.20277778 | E25: 0.0020833333 | F25: 13 - Outros Produção | G25: =VLOOKUP(F25,'Tipo Parada Fab 1'!$A$2:$B$27,2,FALSE()) -> NP | H25: =IF(G25="P",E25,"") | I25: =IF(G25="NP",E25,"") -> 0.0020833333
A26: FN08 | B26: 45022 | C26: 0.47916667 | D26: 0.4875 | E26: 0.0083333333 | F26: 14 - Problema Elétrico | G26: =VLOOKUP(F26,'Tipo Parada Fab 1'!$A$2:$B$27,2,FALSE()) -> NP | H26: =IF(G26="P",E26,"") | I26: =IF(G26="NP",E26,"") -> 0.0083333333
A27: FN08 | B27: 45022 | C27: 0.54791667 | D27: 0.55138889 | E27: 0.0034722222 | F27: 13 - Outros Produção | G27: =VLOOKUP(F27,'Tipo Parada Fab 1'!$A$2:$B$27,2,FALSE()) -> NP | H27: =IF(G27="P",E27,"") | I27: =IF(G27="NP",E27,"") -> 0.0034722222
A28: FN08 | B28: 45022 | C28: 0.66180556 | D28: 0.8125 | E28: 0.15069444 | F28: 26 - Tamponar forno | G28: =VLOOKUP(F28,'Tipo Parada Fab 1'!$A$2:$B$27,2,FALSE()) -> NP | H28: =IF(G28="P",E28,"") | I28: =IF(G28="NP",E28,"") -> 0.15069444
A29: FN08 | B29: 45022 | C29: 0.8125 | D29: 0.875 | E29: 0.0625 | F29: 11 - Modulação | G29: =VLOOKUP(F29,'Tipo Parada Fab 1'!$A$2:$B$27,2,FALSE()) -> P | H29: =IF(G29="P",E29,"") -> 0.0625 | I29: =IF(G29="NP",E29,"")
A30: FN08 | B30: 45023 | C30: 0.36875 | D30: 0.38958333 | E30: 0.020833333 | F30: 10 - Medição de eletrodos | G30: =VLOOKUP(F30,'Tipo Parada Fab 1'!$A$2:$B$27,2,FALSE()) -> NP | H30: =IF(G30="P",E30,"") | I30: =IF(G30="NP",E30,"") -> 0.020833333
A31: FN08 | B31: 45023 | C31: 0.96944444 | D31: 0.99027778 | E31: 0.020833333 | F31: 23 - Sobrecarga | G31: =VLOOKUP(F31,'Tipo Parada Fab 1'!$A$2:$B$27,2,FALSE()) -> NP | H31: =IF(G31="P",E31,"") | I31: =IF(G31="NP",E31,"") -> 0.020833333
A32: FN08 | B32: 45023 | C32: 0.049305556 | D32: 0.0625 | E32: 0.013194444 | F32: 28 - Vazamento de água em flexíveis | G32: =VLOOKUP(F32,'Tipo Parada Fab 1'!$A$2:$B$27,2,FALSE()) -> NP | H32: =IF(G32="P",E32,"") | I32: =IF(G32="NP",E32,"") -> 0.013194444
A33: FN08 | B33: 45024 | C33: 0.0625 | D33: 0.13472222 | E33: 0.072222222 | F33: 28 - Vazamento de água em flexíveis | G33: =VLOOKUP(F33,'Tipo Parada Fab 1'!$A$2:$B$27,2,FALSE()) -> NP | H33: =IF(G33="P",E33,"") | I33: =IF(G33="NP",E33,"") -> 0.072222222
A34: FN08 | B34: 45024 | C34: 0.14097222 | D34: 0.20347222 | E34: 0.0625 | F34: 28 - Vazamento de água em flexíveis | G34: =VLOOKUP(F34,'Tipo Parada Fab 1'!$A$2:$B$27,2,FALSE()) -> NP | H34: =IF(G34="P",E34,"") | I34: =IF(G34="NP",E34,"") -> 0.0625
A35: FN08 | B35: 45024 | C35: 0.43125 | D35: 0.43888889 | E35: 0.0076388889 | F35: 14 - Problema Elétrico | G35: =VLOOKUP(F35,'Tipo Parada Fab 1'!$A$2:$B$27,2,FALSE()) -> NP | H35: =IF(G35="P",E35,"") | I35: =IF(G35="NP",E35,"") -> 0.0076388889
... A139: FN08 | B139: 45046 | C139: 0.059722222 | D139: 0.0625 | E139: 0.0027777778 | F139: 23 - Sobrecarga | G139: =VLOOKUP(F139,'Tipo Parada Fab 1'!$A$2:$B$27,2,FALSE()) -> NP | H139: =IF(G139="P",E139,"") | I139: =IF(G139="NP",E139,"") -> 0.0027777778
E140: =SUM(E2:E139) -> 6.1965278 | H140: =SUM(H2:H139) -> 1.3611111 | I140: =SUM(I2:I139) -> 3.8798611

Sheet Forno 04 07
A1: Forno | B1: Dia | C1: H Inicial | D1: H Final | E1: Duração | F1: Motivo | H1: TIPO | I1: TIPO P | J1: TIPO NP
A2: FN04 | B2: 45017 | C2: 03:18 | D2: 03:23 | E2: 00:05 | F2: QUEBRA DE BORDA / BICA | G2: =VALUE(MID(E2,1,2)+VALUE(MID(E2,4,2))/60) -> 0.083333333 | H2: =VLOOKUP(F2,'Tipo Parada Forno 04 07'!$A$2:I9,2,FALSE()) -> NP | I2: =IF(H2="P",G2,0) -> 0 | J2: =IF(H2="NP",G2,0) -> 0.083333333
A3: FN04 | B3: 45017 | C3: 06:40 | D3: 06:45 | E3: 00:05 | F3: BASCULAMENTO | G3: =VALUE(MID(E3,1,2)+VALUE(MID(E3,4,2))/60) -> 0.083333333 | H3: =VLOOKUP(F3,'Tipo Parada Forno 04 07'!$A$2:I10,2,FALSE()) -> NP | I3: =IF(H3="P",G3,0) -> 0 | J3: =IF(H3="NP",G3,0) -> 0.083333333
A4: FN04 | B4: 45017 | C4: 06:45 | D4: 06:50 | E4: 00:05 | F4: MEDIDA PROFUNDIDADE FORNO | G4: =VALUE(MID(E4,1,2)+VALUE(MID(E4,4,2))/60) -> 0.083333333 | H4: =VLOOKUP(F4,'Tipo Parada Forno 04 07'!$A$2:I11,2,FALSE()) -> NP | I4: =IF(H4="P",G4,0) -> 0 | J4: =IF(H4="NP",G4,0) -> 0.083333333
A5: FN04 | B5: 45017 | C5: 06:50 | D5: 07:00 | E5: 00:10 | F5: DESLIZAMENTO ELETRODO | G5: =VALUE(MID(E5,1,2)+VALUE(MID(E5,4,2))/60) -> 0.16666667 | H5: =VLOOKUP(F5,'Tipo Parada Forno 04 07'!$A$2:I12,2,FALSE()) -> NP | I5: =IF(H5="P",G5,0) -> 0 | J5: =IF(H5="NP",G5,0) -> 0.16666667
A6: FN04 | B6: 45017 | C6: 07:00 | D6: 07:09 | E6: 00:09 | F6: QUEBRA DE BORDA / BICA | G6: =VALUE(MID(E6,1,2)+VALUE(MID(E6,4,2))/60) -> 0.15 | H6: =VLOOKUP(F6,'Tipo Parada Forno 04 07'!$A$2:I13,2,FALSE()) -> NP | I6: =IF(H6="P",G6,0) -> 0 | J6: =IF(H6="NP",G6,0) -> 0.15
A7: FN04 | B7: 45017 | C7: 16:11 | D7: 16:16 | E7: 00:05 | F7: BASCULAMENTO | G7: =VALUE(MID(E7,1,2)+VALUE(MID(E7,4,2))/60) -> 0.083333333 | H7: =VLOOKUP(F7,'Tipo Parada Forno 04 07'!$A$2:I14,2,FALSE()) -> NP | I7: =IF(H7="P",G7,0) -> 0 | J7: =IF(H7="NP",G7,0) -> 0.083333333
A8: FN04 | B8: 45017 | C8: 16:16 | D8: 16:19 | E8: 00:03 | F8: MEDIDA PROFUNDIDADE FORNO | G8: =VALUE(MID(E8,1,2)+VALUE(MID(E8,4,2))/60) -> 0.05 | H8: =VLOOKUP(F8,'Tipo Parada Forno 04 07'!$A$2:I15,2,FALSE()) -> NP | I8: =IF(H8="P",G8,0) -> 0 | J8: =IF(H8="NP",G8,0) -> 0.05
A9: FN04 | B9: 45017 | C9: 16:19 | D9: 16:24 | E9: 00:05 | F9: DESLIZAMENTO ELETRODO | G9: =VALUE(MID(E9,1,2)+VALUE(MID(E9,4,2))/60) -> 0.083333333 | H9: =VLOOKUP(F9,'Tipo Parada Forno 04 07'!$A$2:I16,2,FALSE()) -> NP | I9: =IF(H9="P",G9,0) -> 0 | J9: =IF(H9="NP",G9,0) -> 0.083333333
A10: FN04 | B10: 45017 | C10: 21:49 | D10: 21:54 | E10: 00:05 | F10: BASCULAMENTO | G10: =VALUE(MID(E10,1,2)+VALUE(MID(E10,4,2))/60) -> 0.083333333 | H10: =VLOOKUP(F10,'Tipo Parada Forno 04 07'!$A$2:I17,2,FALSE()) -> NP | I10: =IF(H10="P",G10,0) -> 0 | J10: =IF(H10="NP",G10,0) -> 0.083333333
A11: FN04 | B11: 45017 | C11: 21:54 | D11: 22:00 | E11: 00:06 | F11: MEDIDA PROFUNDIDADE FORNO | G11: =VALUE(MID(E11,1,2)+VALUE(MID(E11,4,2))/60) -> 0.1 | H11: =VLOOKUP(F11,'Tipo Parada Forno 04 07'!$A$2:I18,2,FALSE()) -> NP | I11: =IF(H11="P",G11,0) -> 0 | J11: =IF(H11="NP",G11,0) -> 0.1
A12: FN04 | B12: 45017 | C12: 22:00 | D12: 22:20 | E12: 00:20 | F12: DESLIZAMENTO ELETRODO | G12: =VALUE(MID(E12,1,2)+VALUE(MID(E12,4,2))/60) -> 0.33333333 | H12: =VLOOKUP(F12,'Tipo Parada Forno 04 07'!$A$2:I19,2,FALSE()) -> NP | I12: =IF(H12="P",G12,0) -> 0 | J12: =IF(H12="NP",G12,0) -> 0.33333333
A13: FN04 | B13: 45017 | C13: 22:20 | D13: 22:29 | E13: 00:09 | F13: LIMPEZA DO FOSSO DE REAÇÃO | G13: =VALUE(MID(E13,1,2)+VALUE(MID(E13,4,2))/60) -> 0.15 | H13: =VLOOKUP(F13,'Tipo Parada Forno 04 07'!$A$2:I20,2,FALSE()) -> NP | I13: =IF(H13="P",G13,0) -> 0 | J13: =IF(H13="NP",G13,0) -> 0.15
... A213: FN04 | B213: 45036 | C213: 05:57 | D213: 06:03 | E213: 00:06 | F213: BASCULAMENTO | G213: =VALUE(MID(E213,1,2)+VALUE(MID(E213,4,2))/60) -> 0.1 | H213: =VLOOKUP(F213,'Tipo Parada Forno 04 07'!$A$2:I220,2,FALSE()) -> NP | I213: =IF(H213="P",G213,0) -> 0 | J213: =IF(H213="NP",G213,0) -> 0.1
A214: FN04 | B214: 45036 | C214: 18:42 | D214: 18:45 | E214: 00:03 | F214: BASCULAMENTO | G214: =VALUE(MID(E214,1,2)+VALUE(MID(E214,4,2))/60) -> 0.05 | H214: =VLOOKUP(F214,'Tipo Parada Forno 04 07'!$A$2:I222,2,FALSE()) -> NP | I214: =IF(H214="P",G214,0) -> 0 | J214: =IF(H214="NP",G214,0) -> 0.05
A215: FN04 | B215: 45036 | C215: 18:45 | D215: 18:50 | E215: 00:05 | F215: MEDIDA PROFUNDIDADE FORNO | G215: =VALUE(MID(E215,1,2)+VALUE(MID(E215,4,2))/60) -> 0.083333333 | H215: =VLOOKUP(F215,'Tipo Parada Forno 04 07'!$A$2:I223,2,FALSE()) -> NP | I215: =IF(H215="P",G215,0) -> 0 | J215: =IF(H215="NP",G215,0) -> 0.083333333
A216: FN04 | B216: 45036 | C216: 18:50 | D216: 18:55 | E216: 00:05 | F216: DESLIZAMENTO ELETRODO | G216: =VALUE(MID(E216,1,2)+VALUE(MID(E216,4,2))/60) -> 0.083333333 | H216: =VLOOKUP(F216,'Tipo Parada Forno 04 07'!$A$2:I224,2,FALSE()) -> NP | I216: =IF(H216="P",G216,0) -> 0 | J216: =IF(H216="NP",G216,0) -> 0.083333333
A217: FN04 | B217: 45036 | C217: 18:55 | D217: 19:04 | E217: 00:09 | F217: QUEBRA DE BORDA / BICA | G217: =VALUE(MID(E217,1,2)+VALUE(MID(E217,4,2))/60) -> 0.15 | H217: =VLOOKUP(F217,'Tipo Parada Forno 04 07'!$A$2:I225,2,FALSE()) -> NP | I217: =IF(H217="P",G217,0) -> 0 | J217: =IF(H217="NP",G217,0) -> 0.15
A218: FN04 | B218: 45036 | C218: 21:45 | D218: 21:50 | E218: 00:05 | F218: BASCULAMENTO | G218: =VALUE(MID(E218,1,2)+VALUE(MID(E218,4,2))/60) -> 0.083333333 | H218: =VLOOKUP(F218,'Tipo Parada Forno 04 07'!$A$2:I226,2,FALSE()) -> NP | I218: =IF(H218="P",G218,0) -> 0 | J218: =IF(H218="NP",G218,0) -> 0.083333333
A219: FN04 | B219: 45036 | C219: 21:50 | D219: 21:55 | E219: 00:05 | F219: MEDIDA PROFUNDIDADE FORNO | G219: =VALUE(MID(E219,1,2)+VALUE(MID(E219,4,2))/60) -> 0.083333333 | H219: =VLOOKUP(F219,'Tipo Parada Forno 04 07'!$A$2:I227,2,FALSE()) -> NP | I219: =IF(H219="P",G219,0) -> 0 | J219: =IF(H219="NP",G219,0) -> 0.083333333
A220: FN04 | B220: 45036 | C220: 21:55 | D220: 22:20 | E220: 00:25 | F220: EMENDA DE ELETRODO | G220: =VALUE(MID(E220,1,2)+VALUE(MID(E220,4,2))/60) -> 0.41666667 | H220: =VLOOKUP(F220,'Tipo Parada Forno 04 07'!$A$2:I228,2,FALSE()) -> NP | I220: =IF(H220="P",G220,0) -> 0 | J220: =IF(H220="NP",G220,0) -> 0.41666667
A221: FN04 | B221: 45037 | C221: 04:40 | D221: 04:45 | E221: 00:05 | F221: BASCULAMENTO | G221: =VALUE(MID(E221,1,2)+VALUE(MID(E221,4,2))/60) -> 0.083333333 | H221: =VLOOKUP(F221,'Tipo Parada Forno 04 07'!$A$2:I229,2,FALSE()) -> NP | I221: =IF(H221="P",G221,0) -> 0 | J221: =IF(H221="NP",G221,0) -> 0.083333333
A222: FN04 | B222: 45037 | C222: 05:37 | D222: 05:40 | E222: 00:03 | F222: BASCULAMENTO | G222: =VALUE(MID(E222,1,2)+VALUE(MID(E222,4,2))/60) -> 0.05 | H222: =VLOOKUP(F222,'Tipo Parada Forno 04 07'!$A$2:I230,2,FALSE()) -> NP | I222: =IF(H222="P",G222,0) -> 0 | J222: =IF(H222="NP",G222,0) -> 0.05
A223: FN04 | B223: 45037 | C223: 05:40 | D223: 05:45 | E223: 00:05 | F223: MEDIDA PROFUNDIDADE FORNO | G223: =VALUE(MID(E223,1,2)+VALUE(MID(E223,4,2))/60) -> 0.083333333 | H223: =VLOOKUP(F223,'Tipo Parada Forno 04 07'!$A$2:I231,2,FALSE()) -> NP | I223: =IF(H223="P",G223,0) -> 0 | J223: =IF(H223="NP",G223,0) -> 0.083333333
A224: FN04 | B224: 45037 | C224: 05:45 | D224: 05:59 | E224: 00:14 | F224: DESLIZAMENTO ELETRODO | G224: =VALUE(MID(E224,1,2)+VALUE(MID(E224,4,2))/60) -> 0.23333333 | H224: =VLOOKUP(F224,'Tipo Parada Forno 04 07'!$A$2:I232,2,FALSE()) -> NP | I224: =IF(H224="P",G224,0) -> 0 | J224: =IF(H224="NP",G224,0) -> 0.23333333
A225: FN04 | B225: 45037 | C225: 10:37 | D225: 11:20 | E225: 00:43 | F225: EMENDA DE ELETRODO | G225: =VALUE(MID(E225,1,2)+VALUE(MID(E225,4,2))/60) -> 0.71666667 | H225: =VLOOKUP(F225,'Tipo Parada Forno 04 07'!$A$2:I233,2,FALSE()) -> NP | I225: =IF(H225="P",G225,0) -> 0 | J225: =IF(H225="NP",G225,0) -> 0.71666667
... A482: FN07 | B482: 45046 | C482: 21:45 | D482: 22:32 | E482: 00:47 | F482: EMENDA DE ELETRODO | G482: =VALUE(MID(E482,1,2)+VALUE(MID(E482,4,2))/60) -> 0.78333333 | H482: =VLOOKUP(F482,'Tipo Parada Forno 04 07'!$A$2:I490,2,FALSE()) -> NP | I482: =IF(H482="P",G482,0) -> 0 | J482: =IF(H482="NP",G482,0) -> 0.78333333
G483: =SUM(G2:G482) -> 189.6 | I483: =SUM(I2:I482) -> 71.716667 | J483: =SUM(J2:J482) -> 117.88333

Sheet Forno 09
A1: Forno | B1: Dia | C1: H Inicial | D1: H Final | E1: Duração | F1: Motivo | G1: TIPO | H1: TIPO P | I1: TIPO NP
A2: FN09 | B2: 45017 | C2: 0.12777778 | D2: 0.13055556 | E2: 0.0027777778 | F2: AVALIAR FORNO | G2: =VLOOKUP(F2,'Tipo Parada Fab 2'!$A$1:$B$105,2,FALSE()) -> NP | H2: =IF(G2="P",E2,0) -> 0 | I2: =IF(G2="NP",E2,0) -> 0.0027777778
A3: FN09 | B3: 45018 | C3: 0.12777778 | D3: 0.13055556 | E3: 0.0027777778 | F3: AVALIAR FORNO | G3: =VLOOKUP(F3,'Tipo Parada Fab 2'!$A$1:$B$105,2,FALSE()) -> NP | H3: =IF(G3="P",E3,0) -> 0 | I3: =IF(G3="NP",E3,0) -> 0.0027777778
A4: FN09 | B4: 45019 | C4: 0.74756944 | D4: 0.8125 | E4: 0.064930556 | F4: 38 - HORA DE PONTA | G4: =VLOOKUP(F4,'Tipo Parada Fab 2'!$A$1:$B$105,2,FALSE()) -> P | H4: =IF(G4="P",E4,0) -> 0.064930556 | I4: =IF(G4="NP",E4,0) -> 0
A5: FN09 | B5: 45019 | C5: 0.8125 | D5: 0.87708333 | E5: 0.064583333 | F5: 38 - HORA DE PONTA | G5: =VLOOKUP(F5,'Tipo Parada Fab 2'!$A$1:$B$105,2,FALSE()) -> P | H5: =IF(G5="P",E5,0) -> 0.064583333 | I5: =IF(G5="NP",E5,0) -> 0
A6: FN09 | B6: 45020 | C6: 0.0625 | D6: 0.24583333 | E6: 0.18333333 | F6: RECUPERAÇÃO NA CARCAÇA DO FORNO | G6: =VLOOKUP(F6,'Tipo Parada Fab 2'!$A$1:$B$105,2,FALSE()) -> NP | H6: =IF(G6="P",E6,0) -> 0 | I6: =IF(G6="NP",E6,0) -> 0.18333333
A7: FN09 | B7: 45020 | C7: 0.57152778 | D7: 0.75 | E7: 0.17847222 | F7: SERVIÇO NA CARCAÇA | G7: =VLOOKUP(F7,'Tipo Parada Fab 2'!$A$1:$B$105,2,FALSE()) -> NP | H7: =IF(G7="P",E7,0) -> 0 | I7: =IF(G7="NP",E7,0) -> 0.17847222
A8: FN09 | B8: 45020 | C8: 0.75 | D8: 0.8125 | E8: 0.0625 | F8: 38 - HORA DE PONTA | G8: =VLOOKUP(F8,'Tipo Parada Fab 2'!$A$1:$B$105,2,FALSE()) -> P | H8: =IF(G8="P",E8,0) -> 0.0625 | I8: =IF(G8="NP",E8,0) -> 0
A9: FN09 | B9: 45020 | C9: 0.8125 | D9: 0.875 | E9: 0.0625 | F9: 38 - HORA DE PONTA | G9: =VLOOKUP(F9,'Tipo Parada Fab 2'!$A$1:$B$105,2,FALSE()) -> P | H9: =IF(G9="P",E9,0) -> 0.0625 | I9: =IF(G9="NP",E9,0) -> 0
A10: FN09 | B10: 45020 | C10: 0.875 | D10: 0.0625 | E10: 0.1875 | F10: 88 - OUTROS | G10: =VLOOKUP(F10,'Tipo Parada Fab 2'!$A$1:$B$105,2,FALSE()) -> NP | H10: =IF(G10="P",E10,0) -> 0 | I10: =IF(G10="NP",E10,0) -> 0.1875
A11: FN09 | B11: 45021 | C11: 0.0625 | D11: 0.24583333 | E11: 0.18333333 | F11: RECUPERAÇÃO NA CARCAÇA DO FORNO | G11: =VLOOKUP(F11,'Tipo Parada Fab 2'!$A$1:$B$105,2,FALSE()) -> NP | H11: =IF(G11="P",E11,0) -> 0 | I11: =IF(G11="NP",E11,0) -> 0.18333333
A12: FN09 | B12: 45021 | C12: 0.68472222 | D12: 0.75 | E12: 0.065277778 | F12: 9 - QUEBRA DURA ELETRODO B | G12: =VLOOKUP(F12,'Tipo Parada Fab 2'!$A$1:$B$105,2,FALSE()) -> NP | H12: =IF(G12="P",E12,0) -> 0 | I12: =IF(G12="NP",E12,0) -> 0.065277778
A13: FN09 | B13: 45021 | C13: 0.75 | D13: 0.8125 | E13: 0.0625 | F13: 38 - HORA DE PONTA | G13: =VLOOKUP(F13,'Tipo Parada Fab 2'!$A$1:$B$105,2,FALSE()) -> P | H13: =IF(G13="P",E13,0) -> 0.0625 | I13: =IF(G13="NP",E13,0) -> 0
... A78: FN09 | B78: 45045 | C78: 0.97638889 | D78: 0.99305556 | E78: 0.016666667 | F78: FLUXO FORTE DE LIGA | G78: =VLOOKUP(F78,'Tipo Parada Fab 2'!$A$1:$B$105,2,FALSE()) -> NP | H78: =IF(G78="P",E78,0) -> 0 | I78: =IF(G78="NP",E78,0) -> 0.016666667
E79: =SUM(E2:E78) -> 3.4211806 | H79: =SUM(H2:H78) -> 2.2732639 | I79: =SUM(I2:I78) -> 1.1479167

Sheet Forno 10 a 14
A1: Forno | B1: Dia | C1: H Inicial | D1: H Final | E1: Duração | F1: Motivo | G1: TIPO | H1: TIPO P | I1: TIPO NP
A2: FN10 | B2: 45017 | C2: 0.17847222 | D2: 0.18333333 | E2: 0.0048611111 | F2: 90 - DERRAME DE LIGA | G2: =VLOOKUP(F2,'Tipo Parada Fab 2'!$A$1:$B$105,2,FALSE()) -> NP | H2: =IF(G2="P",E2,0) -> 0 | I2: =IF(G2="NP",E2,0) -> 0.0048611111
A3: FN10 | B3: 45017 | C3: 0.19583333 | D3: 0.20486111 | E3: 0.0090277778 | F3: 90 - DERRAME DE LIGA | G3: =VLOOKUP(F3,'Tipo Parada Fab 2'!$A$1:$B$105,2,FALSE()) -> NP | H3: =IF(G3="P",E3,0) -> 0 | I3: =IF(G3="NP",E3,0) -> 0.0090277778
A4: FN10 | B4: 45017 | C4: 0.52013889 | D4: 0.52361111 | E4: 0.0034722222 | F4: VAZAMENTO ESPONTÂNEO | G4: =VLOOKUP(F4,'Tipo Parada Fab 2'!$A$1:$B$105,2,FALSE()) -> NP | H4: =IF(G4="P",E4,0) -> 0 | I4: =IF(G4="NP",E4,0) -> 0.0034722222
A5: FN10 | B5: 45017 | C5: 0.62569444 | D5: 0.62916667 | E5: 0.0034722222 | F5: 88 - OUTROS | G5: =VLOOKUP(F5,'Tipo Parada Fab 2'!$A$1:$B$105,2,FALSE()) -> NP | H5: =IF(G5="P",E5,0) -> 0 | I5: =IF(G5="NP",E5,0) -> 0.0034722222
A6: FN10 | B6: 45018 | C6: 0.84027778 | D6: 0.86805556 | E6: 0.027777778 | F6: ELIMINAR VASAMENTO DE OLEO MANGUEIRA DE ELEVAÇÃO ELETRODO "B" | G6: =VLOOKUP(F6,'Tipo Parada Fab 2'!$A$1:$B$105,2,FALSE()) -> NP | H6: =IF(G6="P",E6,0) -> 0 | I6: =IF(G6="NP",E6,0) -> 0.027777778
A7: FN10 | B7: 45018 | C7: 0.84027778 | D7: 0.88888889 | E7: 0.048611111 | F7: SOLDAR TRILHO NO CAMINHO DE ROLAMENTO | G7: =VLOOKUP(F7,'Tipo Parada Fab 2'!$A$1:$B$105,2,FALSE()) -> NP | H7: =IF(G7="P",E7,0) -> 0 | I7: =IF(G7="NP",E7,0) -> 0.048611111
A8: FN10 | B8: 45019 | C8: 0.74791667 | D8: 0.8125 | E8: 0.064583333 | F8: 38 - HORA DE PONTA | G8: =VLOOKUP(F8,'Tipo Parada Fab 2'!$A$1:$B$105,2,FALSE()) -> P | H8: =IF(G8="P",E8,0) -> 0.064583333 | I8: =IF(G8="NP",E8,0) -> 0
A9: FN10 | B9: 45019 | C9: 0.8125 | D9: 0.875 | E9: 0.0625 | F9: 38 - HORA DE PONTA | G9: =VLOOKUP(F9,'Tipo Parada Fab 2'!$A$1:$B$105,2,FALSE()) -> P | H9: =IF(G9="P",E9,0) -> 0.0625 | I9: =IF(G9="NP",E9,0) -> 0
A10: FN10 | B10: 45019 | C10: 0.875 | D10: 0.89722222 | E10: 0.022222222 | F10: FINALISANDO SERVIÇO DE SOLDA NOS RILHO DO CAMINHO DE ROLAMENTO | G10: =VLOOKUP(F10,'Tipo Parada Fab 2'!$A$1:$B$105,2,FALSE()) -> NP | H10: =IF(G10="P",E10,0) -> 0 | I10: =IF(G10="NP",E10,0) -> 0.022222222
A11: FN10 | B11: 45020 | C11: 0.74861111 | D11: 0.8125 | E11: 0.063888889 | F11: 38 - HORA DE PONTA | G11: =VLOOKUP(F11,'Tipo Parada Fab 2'!$A$1:$B$105,2,FALSE()) -> P | H11: =IF(G11="P",E11,0) -> 0.063888889 | I11: =IF(G11="NP",E11,0) -> 0
A12: FN10 | B12: 45020 | C12: 0.8125 | D12: 0.87777778 | E12: 0.065277778 | F12: 38 - HORA DE PONTA | G12: =VLOOKUP(F12,'Tipo Parada Fab 2'!$A$1:$B$105,2,FALSE()) -> P | H12: =IF(G12="P",E12,0) -> 0.065277778 | I12: =IF(G12="NP",E12,0) -> 0
A13: FN10 | B13: 45022 | C13: 0.51736111 | D13: 0.52083333 | E13: 0.0034722222 | F13: AVALIAR FORNO | G13: =VLOOKUP(F13,'Tipo Parada Fab 2'!$A$1:$B$105,2,FALSE()) -> NP | H13: =IF(G13="P",E13,0) -> 0 | I13: =IF(G13="NP",E13,0) -> 0.0034722222
... A358: FN14 | B358: 45046 | C358: 0.68125 | D358: 0.68472222 | E358: 0.0034722222 | F358: PROBLEMA DESLIZAMENTO ELETRODO C | G358: =VLOOKUP(F358,'Tipo Parada Fab 2'!$A$1:$B$105,2,FALSE()) -> NP | H358: =IF(G358="P",E358,0) -> 0 | I358: =IF(G358="NP",E358,0) -> 0.0034722222
E359: =SUM(E2:E358) -> 18.048611 | H359: =SUM(H2:H358) -> 10.261806 | I359: =SUM(I2:I358) -> 7.7868056

Sheet Tipo Parada Fab 1
A1: PARADA | B1: TIPO
A2: 11 - Modulação | B2: P
A3: 22 - Recuperação de testa | B3: P
A4: 12 - Outros Mecânica | B4: NP
A5: 13 - Outros Produção | B5: NP
A6: 16 - Problema no Transformador | B6: NP
A7: 8 - Incêndio | B7: NP
A8: 2 - Cortar fita, substituir flexível | B8: NP
A9: 30 - Vazamento de água na placa | B9: NP
A10: 29 - Vazamento de água na coroa | B10: NP
A11: 26 - Tamponar forno | B11: NP
A12: 5 - Deslizamento, sanfona | B12: NP
... A27: 1 - Controlador de demanda | B27: NP

Sheet Tipo Parada Forno 04 07
A1: PARADA | B1: TIPO
A2: QUEBRA DE BORDA / BICA | B2: NP | C2: P
A3: BASCULAMENTO | B3: NP | C3: P
A4: MEDIDA PROFUNDIDADE FORNO | B4: NP | C4: P
A5: DESLIZAMENTO ELETRODO | B5: NP | C5: P
A6: LIMPEZA DO FOSSO DE REAÇÃO | B6: NP | C6: P
A7: EMENDA DE ELETRODO | B7: NP | C7: P
A8: QUEBRA DO ELETRODO C | B8: NP
A9: PROBLEMAS OPERACIONAIS | B9: NP
A10: SERVIÇOS DE SOLDA | B10: NP
A11: OUTROS | B11: NP
A12: HORA DE PONTA | B12: P
A13: PROBLEMAS DE MECANICA | B13: NP
A14: SISTEMA ABASTECIMENTO | B14: NP
A15: VAZAMENTO ÁGUA COROA ELET. A | B15: NP
A16: CONTROLADOR DE DEMANDA | B16: NP
A17: PROBLEMAS DE ELETRICAS | B17: NP
A18: QUEBRA DO ELETRODO B | B18: NP
A19: VAZAMENTO ÁGUA COROA ELET. C | B19: NP
A20: QUEBRA DO ELETRODO A | B20: NP

Sheet Tipo Parada Fab 2
A1: PARADA | B1: TIPO
A2: AVALIAR FORNO | B2: NP
A3: 38 - HORA DE PONTA | B3: P
A4: RECUPERAÇÃO NA CARCAÇA DO FORNO | B4: NP
A5: SERVIÇO NA CARCAÇA | B5: NP
A6: 88 - OUTROS | B6: NP
A7: 9 - QUEBRA DURA ELETRODO B | B7: NP
A8: TRIP BAIXA PRESSÃO DE AGUA NAS COROAS | B8: NP
A9: 52 - MEDIÇÃO DE ELETRODO | B9: NP
A10: TRIP ESCORREGAMENTO | B10: NP
A11: SUBISTITUIR ISOLAÇÃO DO BARRAMENTO | B11: NP
A12: PROBLEMA COM CANAL DE CORRIDA | B12: NP
... A105: PROBLEMA DESLIZAMENTO ELETRODO C | B105: NP

Sheet Abr23
A1: Forno | B1: Dia | C1: H Inicial | D1: H Final | E1: Duração | F1: Motivo | G1: Dia Semana
A2: FN01 | B2: 45019 | C2: 0.74861111 | D2: 0.8125 | E2: 0.063888889 | F2: 11 - Modulação | G2: seg
A3: FN01 | B3: 45019 | C3: 0.8125 | D3: 0.87569444 | E3: 0.063194444 | F3: 11 - Modulação | G3: seg
A4: FN01 | B4: 45020 | C4: 0.74861111 | D4: 0.8125 | E4: 0.063888889 | F4: 11 - Modulação | G4: ter
A5: FN01 | B5: 45020 | C5: 0.8125 | D5: 0.875 | E5: 0.0625 | F5: 11 - Modulação | G5: ter
A6: FN01 | B6: 45020 | C6: 0.875 | D6: 0.99305556 | E6: 0.11805556 | F6: 22 - Recuperação de testa | G6: ter
A7: FN01 | B7: 45020 | C7: 0.99305556 | D7: 0.0034722222 | E7: 0.010416667 | F7: 12 - Outros Mecânica | G7: ter
A8: FN01 | B8: 45021 | C8: 0.74861111 | D8: 0.8125 | E8: 0.063888889 | F8: 11 - Modulação | G8: qua
A9: FN01 | B9: 45021 | C9: 0.8125 | D9: 0.87569444 | E9: 0.063194444 | F9: 11 - Modulação | G9: qua
A10: FN01 | B10: 45022 | C10: 0.74861111 | D10: 0.8125 | E10: 0.063888889 | F10: 11 - Modulação | G10: qui
A11: FN01 | B11: 45022 | C11: 0.8125 | D11: 0.87569444 | E11: 0.063194444 | F11: 11 - Modulação | G11: qui
A12: FN01 | B12: 45022 | C12: 0.89166667 | D12: 0.89305556 | E12: 0.0013888889 | F12: 13 - Outros Produção | G12: qui
A13: FN01 | B13: 45023 | C13: 0.64791667 | D13: 0.67569444 | E13: 0.027777778 | F13: 16 - Problema no Transformador | G13: sex
... A33: FN01 | B33: 45030 | C33: 0.3125 | D33: 0.49305556 | E33: 0.18055556 | F33: 22 - Recuperação de testa | G33: sex
A34: FN01 | B34: 45030 | C34: 0.54513889 | D34: 0.54722222 | E34: 0.0020833333 | G34: sex
A35: FN01 | B35: 45030 | C35: 0.74861111 | D35: 0.8125 | E35: 0.063888889 | F35: 11 - Modulação | G35: sex
A36: FN01 | B36: 45030 | C36: 0.8125 | D36: 0.87777778 | E36: 0.065277778 | F36: 11 - Modulação | G36: sex
A37: FN01 | B37: 45032 | C37: 0.75833333 | D37: 0.7625 | E37: 0.0041666667 | F37: 26 - Tamponar forno | G37: dom
A38: FN01 | B38: 45033 | C38: 0.74861111 | D38: 0.8125 | E38: 0.063888889 | F38: 11 - Modulação | G38: seg
A39: FN01 | B39: 45033 | C39: 0.8125 | D39: 0.875 | E39: 0.0625 | F39: 11 - Modulação | G39: seg
A40: FN01 | B40: 45033 | C40: 0.87569444 | D40: 0.88541667 | E40: 0.0097222222 | F40: 5 - Deslizamento, sanfona | G40: seg
A41: FN01 | B41: 45034 | C41: 0.74861111 | D41: 0.8125 | E41: 0.063888889 | F41: 11 - Modulação | G41: ter
A42: FN01 | B42: 45034 | C42: 0.8125 | D42: 0.87569444 | E42: 0.063194444 | F42: 11 - Modulação | G42: ter
A43: FN01 | B43: 45035 | C43: 0.16805556 | D43: 0.17152778 | E43: 0.0034722222 | F43: 4 - Deslizamento, escorregamento espontâneo | G43: qua
A44: FN01 | B44: 45035 | C44: 0.74861111 | D44: 0.8125 | E44: 0.063888889 | F44: 11 - Modulação | G44: qua
A45: FN01 | B45: 45035 | C45: 0.8125 | D45: 0.87569444 | E45: 0.063194444 | F45: 11 - Modulação | G45: qua
A46: FN01 | B46: 45035 | C46: 0.87569444 | D46: 0.95069444 | E46: 0.075 | F46: 3 - Deslizamento, Anel, Cilindro, Encoder | G46: qua
... A136: FN03 | B136: 45044 | C136: 0.87569444 | D136: 0.94027778 | E136: 0.064583333 | F136: 22 - Recuperação de testa | G136: sex
A137: FN04 | B137: 45017 | C137: 03:18 | D137: 03:23 | E137: 00:05 | F137: QUEBRA DE BORDA / BICA | G137: sáb
A138: FN04 | B138: 45017 | C138: 06:40 | D138: 06:45 | E138: 00:05 | F138: BASCULAMENTO | G138: sáb
A139: FN04 | B139: 45017 | C139: 06:45 | D139: 06:50 | E139: 00:05 | F139: MEDIDA PROFUNDIDADE FORNO | G139: sáb
A140: FN04 | B140: 45017 | C140: 06:50 | D140: 07:00 | E140: 00:10 | F140: DESLIZAMENTO ELETRODO | G140: sáb
A141: FN04 | B141: 45017 | C141: 07:00 | D141: 07:09 | E141: 00:09 | F141: QUEBRA DE BORDA / BICA | G141: sáb
A142: FN04 | B142: 45017 | C142: 16:11 | D142: 16:16 | E142: 00:05 | F142: BASCULAMENTO | G142: sáb
A143: FN04 | B143: 45017 | C143: 16:16 | D143: 16:19 | E143: 00:03 | F143: MEDIDA PROFUNDIDADE FORNO | G143: sáb
A144: FN04 | B144: 45017 | C144: 16:19 | D144: 16:24 | E144: 00:05 | F144: DESLIZAMENTO ELETRODO | G144: sáb
A145: FN04 | B145: 45017 | C145: 21:49 | D145: 21:54 | E145: 00:05 | F145: BASCULAMENTO | G145: sáb
A146: FN04 | B146: 45017 | C146: 21:54 | D146: 22:00 | E146: 00:06 | F146: MEDIDA PROFUNDIDADE FORNO | G146: sáb
A147: FN04 | B147: 45017 | C147: 22:00 | D147: 22:20 | E147: 00:20 | F147: DESLIZAMENTO ELETRODO | G147: sáb
A148: FN04 | B148: 45017 | C148: 22:20 | D148: 22:29 | E148: 00:09 | F148: LIMPEZA DO FOSSO DE REAÇÃO | G148: sáb
...
