Workbook

Sheet Premissas SPS 2024 - Trimestral
B2: Volumes energia (Produtividade) MWh/h
C3: JAN | D3: FEV | E3: MAR | F3: 1T-2024 | G3: ABR | H3: MAI | I3: JUN | J3: 2T-2024 | K3: JUL | L3: AGO | M3: SET | N3: 3T-2024 | O3: OUT | P3: NOV | Q3: DEZ | R3: 4T-2024
B4: CHESF - Consumo | C4: ='Volumes Ajustados'!D25 -> 82.988247 | D4: ='Volumes Ajustados'!E25 -> 82.988247 | E4: ='Volumes Ajustados'!F25 -> 82.988247 | F4: ='Volumes Ajustados'!G25 -> 82.988247 | G4: ='Volumes Ajustados'!G25 -> 82.988247 | H4: ='Volumes Ajustados'!H25 -> 82.988247 | I4: ='Volumes Ajustados'!I25 -> 82.988247 | J4: ='Volumes Ajustados'!K25 -> 82.988247 | K4: ='Volumes Ajustados'!J25 -> 82.988247 | L4: ='Volumes Ajustados'!K25 -> 82.988247 | M4: ='Volumes Ajustados'!L25 -> 82.988247 | N4: ='Volumes Ajustados'!O25 -> 82.988247 | O4: ='Volumes Ajustados'!M25 -> 82.988247 | P4: ='Volumes Ajustados'!N25 -> 82.988247 | Q4: ='Volumes Ajustados'!O25 -> 82.988247 | R4: 82.988247
B5: ML - Consumo (AES, CPFL, PROINFA) | C5: ='Volumes Ajustados'!D26 -> 101.43008 | D5: ='Volumes Ajustados'!E26 -> 101.43008 | E5: ='Volumes Ajustados'!F26 -> 101.43008 | F5: ='Volumes Ajustados'!G26 -> 101.43008 | G5: ='Volumes Ajustados'!G26 -> 101.43008 | H5: ='Volumes Ajustados'!H26 -> 101.43008 | I5: ='Volumes Ajustados'!I26 -> 101.43008 | J5: ='Volumes Ajustados'!K26 -> 101.43008 | K5: ='Volumes Ajustados'!J26 -> 101.43008 | L5: ='Volumes Ajustados'!K26 -> 101.43008 | M5: ='Volumes Ajustados'!L26 -> 101.43008 | N5: ='Volumes Ajustados'!O26 -> 109.36007 | O5: ='Volumes Ajustados'!M26 -> 109.36007 | P5: ='Volumes Ajustados'!N26 -> 109.36007 | Q5: ='Volumes Ajustados'!O26 -> 109.36007 | R5: 101.43008
B6: ML - Mineração - Consumo | C6: ='Energia Aux - Min'!C11 -> 4.5123204 | D6: ='Energia Aux - Min'!D11 -> 4.8235149 | E6: ='Energia Aux - Min'!E11 -> 4.5123204 | F6: 4.6114922 | G6: ='Energia Aux - Min'!F11 -> 4.662731 | H6: ='Energia Aux - Min'!G11 -> 4.5123204 | I6: ='Energia Aux - Min'!H11 -> 4.662731 | J6: 4.6114922 | K6: ='Energia Aux - Min'!I11 -> 4.5123204 | L6: ='Energia Aux - Min'!J11 -> 4.5123204 | M6: ='Energia Aux - Min'!K11 -> 4.662731 | N6: 4.5613673 | O6: ='Energia Aux - Min'!L11 -> 4.5123204 | P6: ='Energia Aux - Min'!M11 -> 4.662731 | Q6: ='Energia Aux - Min'!N11 -> 4.5123204 | R6: 4.5613673
B7: ML - Consumo - Venda | C7: 200 | D7: 200 | E7: 200 | F7: 200 | G7: 200 | H7: 200 | I7: 200 | J7: 200 | K7: 200 | L7: 200 | M7: 200 | N7: 200 | O7: 200 | P7: 200 | Q7: 200 | R7: 200
B8: ML - Mineração - Venda | C8: 5 | D8: 5 | E8: 5 | F8: 5 | G8: 5 | H8: 5 | I8: 5 | J8: 5 | K8: 5 | L8: 5 | M8: 5 | N8: 5 | O8: 5 | P8: 5 | Q8: 5 | R8: 5
B10: Horas Totais | C10: =C11+C12 -> 744 | D10: =D11+D12 -> 696 | E10: =E11+E12 -> 744 | F10: =SUM(C10:E10) -> 2184 | G10: =G11+G12 -> 720 | H10: =H11+H12 -> 744 | I10: =I11+I12 -> 720 | J10: =SUM(G10:I10) -> 2184 | K10: =K11+K12 -> 744 | L10: =L11+L12 -> 744 | M10: =M11+M12 -> 720 | N10: =SUM(K10:M10) -> 2208 | O10: =O11+O12 -> 744 | P10: =P11+P12 -> 720 | Q10: =Q11+Q12 -> 744 | R10: =SUM(O10:Q10) -> 2208
B11: Horas FP | C11: 678 | D11: 636 | E11: 684 | F11: =SUM(C11:E11) -> 1998 | G11: 654 | H11: 681 | I11: 660 | J11: =SUM(G11:I11) -> 1995 | K11: 675 | L11: 678 | M11: 657 | N11: =SUM(K11:M11) -> 2010 | O11: 675 | P11: 660 | Q11: 681 | R11: =SUM(O11:Q11) -> 2016
B12: Horas HP | C12: 66 | D12: 60 | E12: 60 | F12: =SUM(C12:E12) -> 186 | G12: 66 | H12: 63 | I12: 60 | J12: =SUM(G12:I12) -> 189 | K12: 69 | L12: 66 | M12: 63 | N12: =SUM(K12:M12) -> 198 | O12: 69 | P12: 60 | Q12: 63 | R12: =SUM(O12:Q12) -> 192
B15: Custo Consumo de Energia Metalurgia - Pojuca R$/MWh
C16: JAN | D16: FEV | E16: MAR | F16: 1T-2024 | G16: ABR | H16: MAI | I16: JUN | J16: 2T-2024 | K16: JUL | L16: AGO | M16: SET | N16: 3T-2024 | O16: OUT | P16: NOV | Q16: DEZ | R16: 4T-2024
B17: CHESF - Consumo | C17: =SUM(C18:C24) -> 155.26803 | D17: =SUM(D18:D24) -> 157.7133 | E17: =SUM(E18:E24) -> 155.24074 | F17: =SUM(F18:F24) -> 156.15391 | G17: =SUM(G18:G24) -> 156.0098 | H17: =SUM(H18:H24) -> 155.24048 | I17: =SUM(I18:I24) -> 156.01036 | J17: =SUM(J18:J24) -> 155.87944 | ... R17: =SUM(R18:R24) -> 157.18998
B18: Energia | C18: 75.370368 | D18: 75.370368 | E18: 75.370368 | F18: 75.370368 | G18: 75.370368 | H18: 75.370368 | I18: 75.370368 | J18: 75.370368 | K18: 75.370368 | L18: 75.370368 | M18: 75.370368 | N18: 75.370368 | O18: 75.370368 | P18: 75.370368 | Q18: 75.370368 | R18: 75.370368
B19: Transmissão | C19: 22.994081 | D19: 25.457733 | E19: 22.994081 | F19: 23.892188 | G19: 23.760551 | H19: 22.994081 | I19: 23.760551 | J19: 23.629637 | K19: 24.171378 | L19: 24.534685 | M19: 25.352508 | N19: 24.815673 | O19: 24.534685 | P19: 25.352508 | Q19: 24.534685 | R19: 24.93877
B20: Conexão | C20: 0.13222635 | D20: 0.11385216 | E20: 0.1049427 | F20: 0.12 | G20: 0.10753381 | H20: 0.10468044 | I20: 0.10808876 | J20: 0.10808876 | K20: 0.10976578 | L20: 0.11031576 | M20: 0.11333047 | N20: 0.11333047 | O20: 0.10976578 | P20: 0.11333047 | Q20: 0.10949284 | R20: 0.10949284
B21: CDE | C21: 26.038567 | D21: 26.038567 | E21: 26.038567 | F21: 26.038567 | G21: 26.038567 | H21: 26.038567 | I21: 26.038567 | J21: 26.038567 | K21: 26.038567 | L21: 26.038567 | M21: 26.038567 | N21: 26.038567 | O21: 26.038567 | P21: 26.038567 | Q21: 26.038567 | R21: 26.038567
B22: PROINFA | C22: 8.9917355 | D22: 8.9917355 | E22: 8.9917355 | F22: 8.9917355 | G22: 8.9917355 | H22: 8.9917355 | I22: 8.9917355 | J22: 8.9917355 | K22: 8.9917355 | L22: 8.9917355 | M22: 8.9917355 | N22: 8.9917355 | O22: 8.9917355 | P22: 8.9917355 | Q22: 8.9917355 | R22: 8.9917355
B23: ESS | C23: 0.5399449 | D23: 0.5399449 | E23: 0.5399449 | F23: 0.5399449 | G23: 0.5399449 | H23: 0.5399449 | I23: 0.5399449 | J23: 0.5399449 | K23: 0.5399449 | L23: 0.5399449 | M23: 0.5399449 | N23: 0.5399449 | O23: 0.5399449 | P23: 0.5399449 | Q23: 0.5399449 | R23: 0.5399449
B24: EER | C24: 21.201102 | D24: 21.201102 | E24: 21.201102 | F24: 21.201102 | G24: 21.201102 | H24: 21.201102 | I24: 21.201102 | J24: 21.201102 | K24: 21.201102 | L24: 21.201102 | M24: 21.201102 | N24: 21.201102 | O24: 21.201102 | P24: 21.201102 | Q24: 21.201102 | R24: 21.201102
B26: ML POJUCA - Consumo | C26: =SUM(C27:C33) -> 218.25218 | D26: =SUM(D27:D33) -> 220.69746 | E26: =SUM(E27:E33) -> 218.2249 | F26: =SUM(F27:F33) -> 219.13806 | G26: =SUM(G27:G33) -> 218.99396 | H26: =SUM(H27:H33) -> 218.22464 | I26: =SUM(I27:I33) -> 218.99451 | J26: =SUM(J27:J33) -> 218.8636 | ... R26: =SUM(R27:R33) -> 220.17414
B27: Energia | C27: 138.35452 | D27: 138.35452 | E27: 138.35452 | F27: 138.35452 | G27: 138.35452 | H27: 138.35452 | I27: 138.35452 | J27: 138.35452 | K27: 138.35452 | L27: 138.35452 | M27: 138.35452 | N27: 138.35452 | O27: 138.35452 | P27: 138.35452 | Q27: 138.35452 | R27: 138.35452
B28: Transmissão | C28: 22.994081 | D28: 25.457733 | E28: 22.994081 | F28: 23.892188 | G28: 23.760551 | H28: 22.994081 | I28: 23.760551 | J28: 23.629637 | K28: 24.171378 | L28: 24.534685 | M28: 25.352508 | N28: 24.815673 | O28: 24.534685 | P28: 25.352508 | Q28: 24.534685 | R28: 24.93877
B29: Conexão | C29: 0.13222635 | D29: 0.11385216 | E29: 0.1049427 | F29: 0.12 | G29: 0.10753381 | H29: 0.10468044 | I29: 0.10808876 | J29: 0.10808876 | K29: 0.10976578 | L29: 0.11031576 | M29: 0.11333047 | N29: 0.11333047 | O29: 0.10976578 | P29: 0.11333047 | Q29: 0.10949284 | R29: 0.10949284
B30: CDE | C30: 26.038567 | D30: 26.038567 | E30: 26.038567 | F30: 26.038567 | G30: 26.038567 | H30: 26.038567 | I30: 26.038567 | J30: 26.038567 | K30: 26.038567 | L30: 26.038567 | M30: 26.038567 | N30: 26.038567 | O30: 26.038567 | P30: 26.038567 | Q30: 26.038567 | R30: 26.038567
B31: PROINFA | C31: 8.9917355 | D31: 8.9917355 | E31: 8.9917355 | F31: 8.9917355 | G31: 8.9917355 | H31: 8.9917355 | I31: 8.9917355 | J31: 8.9917355 | K31: 8.9917355 | L31: 8.9917355 | M31: 8.9917355 | N31: 8.9917355 | O31: 8.9917355 | P31: 8.9917355 | Q31: 8.9917355 | R31: 8.9917355
B32: ESS | C32: 0.5399449 | D32: 0.5399449 | E32: 0.5399449 | F32: 0.5399449 | G32: 0.5399449 | H32: 0.5399449 | I32: 0.5399449 | J32: 0.5399449 | K32: 0.5399449 | L32: 0.5399449 | M32: 0.5399449 | N32: 0.5399449 | O32: 0.5399449 | P32: 0.5399449 | Q32: 0.5399449 | R32: 0.5399449
B33: EER | C33: 21.201102 | D33: 21.201102 | E33: 21.201102 | F33: 21.201102 | G33: 21.201102 | H33: 21.201102 | I33: 21.201102 | J33: 21.201102 | K33: 21.201102 | L33: 21.201102 | M33: 21.201102 | N33: 21.201102 | O33: 21.201102 | P33: 21.201102 | Q33: 21.201102 | R33: 21.201102
B35: Custo Contratos ML POJUCA | C35: 120.42415 | D35: 120.42415 | E35: 120.42415 | F35: 120.42415 | G35: 120.42415 | H35: 120.42415 | I35: 120.42415 | J35: 120.42415 | K35: 120.42415 | L35: 120.42415 | M35: 120.42415 | N35: 120.42415 | O35: 120.42415 | P35: 120.42415 | Q35: 120.42415 | R35: 120.42415
B38: Custo Consumo de Energia Mineração - Andorinha R$/MWh
C39: JAN | D39: FEV | E39: MAR | F39: 1T-2024 | G39: ABR | H39: MAI | I39: JUN | J39: 2T-2024 | K39: JUL | L39: AGO | M39: SET | N39: 3T-2024 | O39: OUT | P39: NOV | Q39: DEZ | R39: 4T-2024
B40: Custo Consumo Mineração | C40: =SUM(C41:C43) -> 345.29412 | D40: =SUM(D41:D43) -> 345.29412 | E40: =SUM(E41:E43) -> 345.29412 | F40: =SUM(F41:F43) -> 345.29412 | G40: =SUM(G41:G43) -> 345.29412 | H40: =SUM(H41:H43) -> 345.29412 | I40: =SUM(I41:I43) -> 345.29412 | J40: =SUM(J41:J43) -> 345.29412 | ... R40: =SUM(R41:R43) -> 345.29412
B41: Energia | C41: ='[1]Reajuste Energia'!$C$7 -> 200.80444 | D41: ='[1]Reajuste Energia'!$C$7 -> 200.80444 | E41: ='[1]Reajuste Energia'!$C$7 -> 200.80444 | F41: ='[1]Reajuste Energia'!$C$7 -> 200.80444 | G41: ='[1]Reajuste Energia'!$C$7 -> 200.80444 | H41: ='[1]Reajuste Energia'!$C$7 -> 200.80444 | I41: ='[1]Reajuste Energia'!$C$7 -> 200.80444 | J41: ='[1]Reajuste Energia'!$C$7 -> 200.80444 | ... R41: ='[1]Reajuste Energia'!$C$7 -> 200.80444
B42: Transmissão | C42: 91.509677 | D42: 91.509677 | E42: 91.509677 | F42: 91.509677 | G42: 91.509677 | H42: 91.509677 | I42: 91.509677 | J42: 91.509677 | K42: 91.509677 | L42: 91.509677 | M42: 91.509677 | N42: 91.509677 | O42: 91.509677 | P42: 91.509677 | Q42: 91.509677 | R42: 91.509677
B43: Encargos | C43: 52.98 | D43: 52.98 | E43: 52.98 | F43: 52.98 | G43: 52.98 | H43: 52.98 | I43: 52.98 | J43: 52.98 | K43: 52.98 | L43: 52.98 | M43: 52.98 | N43: 52.98 | O43: 52.98 | P43: 52.98 | Q43: 52.98 | R43: 52.98
B45: Custo Contratos ML Andorinha | C45: ='[1]Reajuste Energia'!$C$6 -> 221.27211 | D45: ='[1]Reajuste Energia'!$C$6 -> 221.27211 | E45: ='[1]Reajuste Energia'!$C$6 -> 221.27211 | F45: ='[1]Reajuste Energia'!$C$6 -> 221.27211 | G45: ='[1]Reajuste Energia'!$C$6 -> 221.27211 | H45: ='[1]Reajuste Energia'!$C$6 -> 221.27211 | I45: ='[1]Reajuste Energia'!$C$6 -> 221.27211 | J45: ='[1]Reajuste Energia'!$C$6 -> 221.27211 | ... R45: ='[1]Reajuste Energia'!$C$6 -> 221.27211
B47: Custo Consumo Mercado SPOT - Metalurgia Pojuca R$/MWh
C48: JAN | D48: FEV | E48: MAR | F48: 1T-2024 | G48: ABR | H48: MAI | I48: JUN | J48: 2T-2024 | K48: JUL | L48: AGO | M48: SET | N48: 3T-2024 | O48: OUT | P48: NOV | Q48: DEZ | R48: 4T-2024
B49: Compra SPOT para consumo | C49: =SUM(C50:C56) -> 148.41766 | D49: =SUM(D50:D56) -> 150.86294 | E49: =SUM(E50:E56) -> 148.39037 | F49: =SUM(F50:F56) -> 149.30354 | G49: =SUM(G50:G56) -> 149.15943 | H49: =SUM(H50:H56) -> 148.39011 | I49: =SUM(I50:I56) -> 149.15999 | J49: =SUM(J50:J56) -> 149.02908 | ... R49: =SUM(R50:R56) -> 153.31961
B50: Energia | C50: 68.52 | D50: 68.52 | E50: 68.52 | F50: 68.52 | G50: 68.52 | H50: 68.52 | I50: 68.52 | J50: 68.52 | K50: 70.5 | L50: 70.5 | M50: 70.5 | N50: 70.5 | O50: 71.5 | P50: 71.5 | Q50: 71.5 | R50: 71.5
...

Sheet Premissas SPS 2024 - Mensal
B2: Volumes energia (Produtividade) MWh/h
C3: JAN | D3: FEV | E3: MAR | F3: ABR | G3: MAI | H3: JUN | I3: JUL | J3: AGO | K3: SET | L3: OUT | M3: NOV | N3: DEZ
B4: CHESF - Consumo | C4: ='Volumes Ajustados'!D25 -> 82.988247 | D4: ='Volumes Ajustados'!E25 -> 82.988247 | E4: ='Volumes Ajustados'!F25 -> 82.988247 | F4: ='Volumes Ajustados'!G25 -> 82.988247 | G4: ='Volumes Ajustados'!H25 -> 82.988247 | H4: ='Volumes Ajustados'!I25 -> 82.988247 | I4: ='Volumes Ajustados'!J25 -> 82.988247 | J4: ='Volumes Ajustados'!K25 -> 82.988247 | ... N4: ='Volumes Ajustados'!O25 -> 82.988247
B5: ML - Consumo (AES, CPFL, PROINFA) | C5: ='Volumes Ajustados'!D26 -> 101.43008 | D5: ='Volumes Ajustados'!E26 -> 101.43008 | E5: ='Volumes Ajustados'!F26 -> 101.43008 | F5: ='Volumes Ajustados'!G26 -> 101.43008 | G5: ='Volumes Ajustados'!H26 -> 101.43008 | H5: ='Volumes Ajustados'!I26 -> 101.43008 | I5: ='Volumes Ajustados'!J26 -> 101.43008 | J5: ='Volumes Ajustados'!K26 -> 101.43008 | ... N5: ='Volumes Ajustados'!O26 -> 109.36007
B6: ML - Mineração - Consumo | C6: ='Energia Aux - Min'!C11 -> 4.5123204 | D6: ='Energia Aux - Min'!D11 -> 4.8235149 | E6: ='Energia Aux - Min'!E11 -> 4.5123204 | F6: ='Energia Aux - Min'!F11 -> 4.662731 | G6: ='Energia Aux - Min'!G11 -> 4.5123204 | H6: ='Energia Aux - Min'!H11 -> 4.662731 | I6: ='Energia Aux - Min'!I11 -> 4.5123204 | J6: ='Energia Aux - Min'!J11 -> 4.5123204 | ... N6: ='Energia Aux - Min'!N11 -> 4.5123204
B7: ML - Consumo - Venda | C7: 200 | D7: 200 | E7: 200 | F7: 200 | G7: 200 | H7: 200 | I7: 200 | J7: 200 | K7: 200 | L7: =SUM(Plan1!D4:D6) -> 118.6 | M7: =SUM(Plan1!E4:E6) -> 118.6 | N7: =SUM(Plan1!F4:F6) -> 118.6
B8: ML - Mineração - Venda | C8: 5 | D8: 5 | E8: 5 | F8: 5 | G8: 5 | H8: 5 | I8: 5 | J8: 5 | K8: 5 | L8: 5 | M8: 5 | N8: 5
B10: Horas Totais | C10: =C11+C12 -> 744 | D10: =D11+D12 -> 696 | E10: =E11+E12 -> 744 | F10: =F11+F12 -> 720 | G10: =G11+G12 -> 744 | H10: =H11+H12 -> 720 | I10: =I11+I12 -> 744 | J10: =J11+J12 -> 744 | ... N10: =N11+N12 -> 744
B11: Horas FP | C11: 678 | D11: 636 | E11: 684 | F11: 654 | G11: 681 | H11: 660 | I11: 675 | J11: 678 | K11: 657 | L11: 675 | M11: 660 | N11: 681
B12: Horas HP | C12: 66 | D12: 60 | E12: 60 | F12: 66 | G12: 63 | H12: 60 | I12: 69 | J12: 66 | K12: 63 | L12: 69 | M12: 60 | N12: 63
B15: Custo Consumo de Energia Metalurgia - Pojuca R$/MWh
C16: JAN | D16: FEV | E16: MAR | F16: ABR | G16: MAI | H16: JUN | I16: JUL | J16: AGO | K16: SET | L16: OUT | M16: NOV | N16: DEZ
B17: CHESF - Consumo | C17: =SUM(C18:C24) -> 155.26803 | D17: =SUM(D18:D24) -> 157.7133 | E17: =SUM(E18:E24) -> 155.24074 | F17: =SUM(F18:F24) -> 156.0098 | G17: =SUM(G18:G24) -> 155.24048 | H17: =SUM(H18:H24) -> 156.01036 | I17: =SUM(I18:I24) -> 156.42286 | J17: =SUM(J18:J24) -> 156.78672 | ... N17: =SUM(N18:N24) -> 137.95071
B18: Energia | C18: 75.370368 | D18: 75.370368 | E18: 75.370368 | F18: 75.370368 | G18: 75.370368 | H18: 75.370368 | I18: 75.370368 | J18: 75.370368 | K18: 75.370368 | L18: =Plan1!D21 -> 74.39685 | M18: =Plan1!E21 -> 74.39685 | N18: =Plan1!F21 -> 74.39685
B19: Transmissão | C19: 22.994081 | D19: 25.457733 | E19: 22.994081 | F19: 23.760551 | G19: 22.994081 | H19: 23.760551 | I19: 24.171378 | J19: 24.534685 | K19: 25.352508 | L19: 22.058869 | M19: 23.175269 | N19: 22.649173
B20: Conexão | C20: 0.13222635 | D20: 0.11385216 | E20: 0.1049427 | F20: 0.10753381 | G20: 0.10468044 | H20: 0.10808876 | I20: 0.10976578 | J20: 0.11031576 | K20: 0.11333047 | L20: 0.13196504 | M20: 0.13636387 | N20: 0.13196504
B21: CDE | C21: 26.038567 | D21: 26.038567 | E21: 26.038567 | F21: 26.038567 | G21: 26.038567 | H21: 26.038567 | I21: 26.038567 | J21: 26.038567 | K21: 26.038567 | L21: 20.645559 | M21: 22.47103 | N21: 21.838117
B22: PROINFA | C22: 8.9917355 | D22: 8.9917355 | E22: 8.9917355 | F22: 8.9917355 | G22: 8.9917355 | H22: 8.9917355 | I22: 8.9917355 | J22: 8.9917355 | K22: 8.9917355 | L22: 9.9876775 | M22: 10.870784 | N22: 10.5646
B23: ESS | C23: 0.5399449 | D23: 0.5399449 | E23: 0.5399449 | F23: 0.5399449 | G23: 0.5399449 | H23: 0.5399449 | I23: 0.5399449 | J23: 0.5399449 | K23: 0.5399449 | L23: 9.59 | M23: 5.82 | N23: 2.34
B24: EER | C24: 21.201102 | D24: 21.201102 | E24: 21.201102 | F24: 21.201102 | G24: 21.201102 | H24: 21.201102 | I24: 21.201102 | J24: 21.201102 | K24: 21.201102 | L24: 15.09 | M24: 0 | N24: 6.03
B26: ML POJUCA - Consumo | C26: =SUM(C27:C33) -> 218.25218 | D26: =SUM(D27:D33) -> 220.69746 | E26: =SUM(E27:E33) -> 218.2249 | F26: =SUM(F27:F33) -> 218.99396 | G26: =SUM(G27:G33) -> 218.22464 | H26: =SUM(H27:H33) -> 218.99451 | I26: =SUM(I27:I33) -> 219.40702 | J26: =SUM(J27:J33) -> 219.77087 | ... N26: =SUM(N27:N33) -> 199.58586
B27: Energia | C27: 138.35452 | D27: 138.35452 | E27: 138.35452 | F27: 138.35452 | G27: 138.35452 | H27: 138.35452 | I27: 138.35452 | J27: 138.35452 | K27: 138.35452 | L27: =Plan1!D30 -> 136.032 | M27: =Plan1!E30 -> 136.032 | N27: =Plan1!F30 -> 136.032
B28: Transmissão | C28: 22.994081 | D28: 25.457733 | E28: 22.994081 | F28: 23.760551 | G28: 22.994081 | H28: 23.760551 | I28: 24.171378 | J28: 24.534685 | K28: 25.352508 | L28: 22.058869 | M28: 23.175269 | N28: 22.649173
B29: Conexão | C29: 0.13222635 | D29: 0.11385216 | E29: 0.1049427 | F29: 0.10753381 | G29: 0.10468044 | H29: 0.10808876 | I29: 0.10976578 | J29: 0.11031576 | K29: 0.11333047 | L29: 0.13196504 | M29: 0.13636387 | N29: 0.13196504
B30: CDE | C30: 26.038567 | D30: 26.038567 | E30: 26.038567 | F30: 26.038567 | G30: 26.038567 | H30: 26.038567 | I30: 26.038567 | J30: 26.038567 | K30: 26.038567 | L30: 20.645559 | M30: 22.47103 | N30: 21.838117
B31: PROINFA | C31: 8.9917355 | D31: 8.9917355 | E31: 8.9917355 | F31: 8.9917355 | G31: 8.9917355 | H31: 8.9917355 | I31: 8.9917355 | J31: 8.9917355 | K31: 8.9917355 | L31: 9.9876775 | M31: 10.870784 | N31: 10.5646
B32: ESS | C32: 0.5399449 | D32: 0.5399449 | E32: 0.5399449 | F32: 0.5399449 | G32: 0.5399449 | H32: 0.5399449 | I32: 0.5399449 | J32: 0.5399449 | K32: 0.5399449 | L32: 9.59 | M32: 5.82 | N32: 2.34
B33: EER | C33: 21.201102 | D33: 21.201102 | E33: 21.201102 | F33: 21.201102 | G33: 21.201102 | H33: 21.201102 | I33: 21.201102 | J33: 21.201102 | K33: 21.201102 | L33: 15.09 | M33: 0 | N33: 6.03
B35: Custo Contratos ML POJUCA | C35: 120.42415 | D35: 120.42415 | E35: 120.42415 | F35: 120.42415 | G35: 120.42415 | H35: 120.42415 | I35: 120.42415 | J35: 120.42415 | K35: 120.42415 | L35: 120.42415 | M35: 120.42415 | N35: 120.42415
B38: Custo Consumo de Energia Mineração - Andorinha R$/MWh
C39: JAN | D39: FEV | E39: MAR | F39: ABR | G39: MAI | H39: JUN | I39: JUL | J39: AGO | K39: SET | L39: OUT | M39: NOV | N39: DEZ
B40: Custo Consumo Mineração | C40: =SUM(C41:C43) -> 345.29412 | D40: =SUM(D41:D43) -> 345.29412 | E40: =SUM(E41:E43) -> 345.29412 | F40: =SUM(F41:F43) -> 345.29412 | G40: =SUM(G41:G43) -> 345.29412 | H40: =SUM(H41:H43) -> 345.29412 | I40: =SUM(I41:I43) -> 345.29412 | J40: =SUM(J41:J43) -> 345.29412 | ... N40: =SUM(N41:N43) -> 201.90318
B41: Energia | C41: ='[1]Reajuste Energia'!$C$7 -> 200.80444 | D41: ='[1]Reajuste Energia'!$C$7 -> 200.80444 | E41: ='[1]Reajuste Energia'!$C$7 -> 200.80444 | F41: ='[1]Reajuste Energia'!$C$7 -> 200.80444 | G41: ='[1]Reajuste Energia'!$C$7 -> 200.80444 | H41: ='[1]Reajuste Energia'!$C$7 -> 200.80444 | I41: ='[1]Reajuste Energia'!$C$7 -> 200.80444 | J41: ='[1]Reajuste Energia'!$C$7 -> 200.80444 | K41: ='[1]Reajuste Energia'!$C$7 -> 200.80444 | L41: =Plan1!D25 -> 97.19325 | M41: =Plan1!E25 -> 97.19325 | N41: =Plan1!F25 -> 97.19325
B42: Transmissão | C42: 91.509677 | D42: 91.509677 | E42: 91.509677 | F42: 91.509677 | G42: 91.509677 | H42: 91.509677 | I42: 91.509677 | J42: 91.509677 | K42: 91.509677 | L42: 51.333836 | M42: 51.333836 | N42: 51.333836
B43: Encargos | C43: 52.98 | D43: 52.98 | E43: 52.98 | F43: 52.98 | G43: 52.98 | H43: 52.98 | I43: 52.98 | J43: 52.98 | K43: 52.98 | L43: 53.376095 | M43: 53.376095 | N43: 53.376095
B45: Custo Contratos ML Andorinha | C45: ='[1]Reajuste Energia'!$C$6 -> 221.27211 | D45: ='[1]Reajuste Energia'!$C$6 -> 221.27211 | E45: ='[1]Reajuste Energia'!$C$6 -> 221.27211 | F45: ='[1]Reajuste Energia'!$C$6 -> 221.27211 | G45: ='[1]Reajuste Energia'!$C$6 -> 221.27211 | H45: ='[1]Reajuste Energia'!$C$6 -> 221.27211 | I45: ='[1]Reajuste Energia'!$C$6 -> 221.27211 | J45: ='[1]Reajuste Energia'!$C$6 -> 221.27211 | ... N45: ='[1]Reajuste Energia'!$C$6 -> 221.27211
B47: Custo Consumo Mercado SPOT - Metalurgia Pojuca R$/MWh
C48: JAN | D48: FEV | E48: MAR | F48: ABR | G48: MAI | H48: JUN | I48: JUL | J48: AGO | K48: SET | L48: OUT | M48: NOV | N48: DEZ
B49: Compra SPOT para consumo | C49: =SUM(C50:C56) -> 148.41766 | D49: =SUM(D50:D56) -> 148.41766 | E49: =SUM(E50:E56) -> 148.41766 | F49: =SUM(F50:F56) -> 148.41766 | G49: =SUM(G50:G56) -> 148.41766 | H49: =SUM(H50:H56) -> 148.41766 | I49: =SUM(I50:I56) -> 150.39766 | J49: =SUM(J50:J56) -> 150.39766 | ... N49: =SUM(N50:N56) -> 425.89386
B50: Energia | C50: 68.52 | D50: 68.52 | E50: 68.52 | F50: 68.52 | G50: 68.52 | H50: 68.52 | I50: 70.5 | J50: 70.5 | K50: 70.5 | L50: 595.27 | M50: 489.1 | N50: 362.34
...

Sheet Volumes Ajustados
C2: Pojuca | D2: JAN | E2: FEV | F2: MAR | G2: ABR | H2: MAI | I2: JUN | J2: JUL | K2: AGO | L2: SET | M2: OUT | N2: NOV | O2: DEZ
B3: Produtividade MWh/h | C3: CHESF | D3: 90 | E3: 90 | F3: 90 | G3: 90 | H3: 90 | I3: 90 | J3: 90 | K3: 90 | L3: 90 | M3: 90 | N3: 90 | O3: 90
C4: ML - POJUCA | D4: 110 | E4: 110 | F4: 110 | G4: 110 | H4: 110 | I4: 110 | J4: 110 | K4: 110 | L4: 110 | M4: =SUM(Plan1!D4:D6) -> 118.6 | N4: =SUM(Plan1!E4:E6) -> 118.6 | O4: =SUM(Plan1!F4:F6) -> 118.6
C5: ML - Mineração | D5: 5 | E5: 5 | F5: 5 | G5: 5 | H5: 5 | I5: 5 | J5: 5 | K5: 5 | L5: 5 | M5: 5 | N5: 5 | O5: 5
C6: Horas Totais | D6: ='Premissas SPS 2024 - Mensal'!C10 -> 744 | E6: ='Premissas SPS 2024 - Mensal'!D10 -> 696 | F6: ='Premissas SPS 2024 - Mensal'!E10 -> 744 | G6: ='Premissas SPS 2024 - Mensal'!F10 -> 720 | H6: ='Premissas SPS 2024 - Mensal'!G10 -> 744 | I6: ='Premissas SPS 2024 - Mensal'!H10 -> 720 | J6: ='Premissas SPS 2024 - Mensal'!I10 -> 744 | K6: ='Premissas SPS 2024 - Mensal'!J10 -> 744 | ... O6: ='Premissas SPS 2024 - Mensal'!N10 -> 744
B8: Volume MWh | C8: CHESF | D8: =D3*D$6 -> 66960 | E8: =E3*E$6 -> 62640 | F8: =F3*F$6 -> 66960 | G8: =G3*G$6 -> 64800 | H8: =H3*H$6 -> 66960 | I8: =I3*I$6 -> 64800 | J8: =J3*J$6 -> 66960 | K8: =K3*K$6 -> 66960 | ... O8: =O3*O$6 -> 66960
C9: ML | D9: =D4*D$6 -> 81840 | E9: =E4*E$6 -> 76560 | F9: =F4*F$6 -> 81840 | G9: =G4*G$6 -> 79200 | H9: =H4*H$6 -> 81840 | I9: =I4*I$6 -> 79200 | J9: =J4*J$6 -> 81840 | K9: =K4*K$6 -> 81840 | ... O9: =O4*O$6 -> 88238.4
C10: Total - Metalurgia | D10: =D8+D9 -> 148800 | E10: =E8+E9 -> 139200 | F10: =F8+F9 -> 148800 | G10: =G8+G9 -> 144000 | H10: =H8+H9 -> 148800 | I10: =I8+I9 -> 144000 | J10: =J8+J9 -> 148800 | K10: =K8+K9 -> 148800 | ... O10: =O8+O9 -> 155198.4
C11: ML - Mineração | D11: =D5*D$6 -> 3720 | E11: =E5*E$6 -> 3480 | F11: =F5*F$6 -> 3720 | G11: =G5*G$6 -> 3600 | H11: =H5*H$6 -> 3720 | I11: =I5*I$6 -> 3600 | J11: =J5*J$6 -> 3720 | K11: =K5*K$6 -> 3720 | ... O11: =O5*O$6 -> 3720
B13: Fator Participação
B14: Forno | C14: ='Energia Aux - Met'!S58 -> 0.95060968
B15: Auxiliar | C15: ='Energia Aux - Met'!T58 -> 0.049390065
B17: Ajuste- Retira Energia Auxiliar | C17: CHESF | D17: =D8*$C$15 -> 3307.1588 | E17: =E8*$C$15 -> 3093.7937 | F17: =F8*$C$15 -> 3307.1588 | G17: =G8*$C$15 -> 3200.4762 | H17: =H8*$C$15 -> 3307.1588 | I17: =I8*$C$15 -> 3200.4762 | J17: =J8*$C$15 -> 3307.1588 | K17: =K8*$C$15 -> 3307.1588 | ... O17: =O8*$C$15 -> 3307.1588
C18: ML | D18: =D9*$C$15 -> 4042.0829 | E18: =E9*$C$15 -> 3781.3034 | F18: =F9*$C$15 -> 4042.0829 | G18: =G9*$C$15 -> 3911.6932 | H18: =H9*$C$15 -> 4042.0829 | I18: =I9*$C$15 -> 3911.6932 | J18: =J9*$C$15 -> 4042.0829 | K18: =K9*$C$15 -> 4042.0829 | ... O18: =O9*$C$15 -> 4358.1003
B20: Perdas | C20: CHESF | D20: =(D8-D17)*$B$22 -> 1909.5852 | E20: =(E8-E17)*$B$22 -> 1786.3862 | F20: =(F8-F17)*$B$22 -> 1909.5852 | G20: =(G8-G17)*$B$22 -> 1847.9857 | H20: =(H8-H17)*$B$22 -> 1909.5852 | I20: =(I8-I17)*$B$22 -> 1847.9857 | J20: =(J8-J17)*$B$22 -> 1909.5852 | K20: =(K8-K17)*$B$22 -> 1909.5852 | ... O20: =(O8-O17)*$B$22 -> 1909.5852
C21: ML | D21: =(D9-D18)*$B$22 -> 2333.9375 | E21: =(E9-E18)*$B$22 -> 2183.3609 | F21: =(F9-F18)*$B$22 -> 2333.9375 | G21: =(G9-G18)*$B$22 -> 2258.6492 | H21: =(H9-H18)*$B$22 -> 2333.9375 | I21: =(I9-I18)*$B$22 -> 2258.6492 | J21: =(J9-J18)*$B$22 -> 2333.9375 | K21: =(K9-K18)*$B$22 -> 2333.9375 | ... O21: =(O9-O18)*$B$22 -> 2516.409
B22: 0.03 | C22: Total | D22: =D20+D21 -> 4243.5227 | E22: =E20+E21 -> 3969.7471 | F22: =F20+F21 -> 4243.5227 | G22: =G20+G21 -> 4106.6349 | H22: =H20+H21 -> 4243.5227 | I22: =I20+I21 -> 4106.6349 | J22: =J20+J21 -> 4243.5227 | K22: =K20+K21 -> 4243.5227 | ... O22: =O20+O21 -> 4425.9942
B25: Produtividade MWh/h Ajustada | C25: CHESF | D25: =(D8-D17-D20)/D6 -> 82.988247 | E25: =(E8-E17-E20)/E6 -> 82.988247 | F25: =(F8-F17-F20)/F6 -> 82.988247 | G25: =(G8-G17-G20)/G6 -> 82.988247 | H25: =(H8-H17-H20)/H6 -> 82.988247 | I25: =(I8-I17-I20)/I6 -> 82.988247 | J25: =(J8-J17-J20)/J6 -> 82.988247 | K25: =(K8-K17-K20)/K6 -> 82.988247 | ... O25: =(O8-O17-O20)/O6 -> 82.988247
C26: ML | D26: =(D9-D18-D21)/D6 -> 101.43008 | E26: =(E9-E18-E21)/E6 -> 101.43008 | F26: =(F9-F18-F21)/F6 -> 101.43008 | G26: =(G9-G18-G21)/G6 -> 101.43008 | H26: =(H9-H18-H21)/H6 -> 101.43008 | I26: =(I9-I18-I21)/I6 -> 101.43008 | J26: =(J9-J18-J21)/J6 -> 101.43008 | K26: =(K9-K18-K21)/K6 -> 101.43008 | ... O26: =(O9-O18-O21)/O6 -> 109.36007

Sheet Energia Aux - Met
B3: Mês | C3: Energia Fornos Fora Ponta (717007) | D3: Energia Fornos Hora Ponta (717008) | E3: Subtotal FORNOS | G3: Sinterização + Aux Fornos FP (Direto) | H3: Sinterização + Aux Fornos HP (Direto) | I3: Subtotal | K3: Auxiliar Fora Ponta (Sem Sinterização e Forno) (717003) | L3: Auxiliar Hora Ponta (Sem Sinterização e Forno) (717004) | M3: Subtotal Aux | O3: Medidor SMART1 FP | P3: Medidor SMART1 HP | Q3: TOTAL Medidor SMART1 | S3: Forno | T3: Auxiliar | V3: 717007 | W3: 717008 | X3: 717003 | Y3: 717004
B4: 43466 | C4: ='[2]Consumo Diário'!$C$42 -> 128045.3 | D4: ='[2]Consumo Diário'!$D$42 -> 1038.452 | E4: =C4+D4 -> 129083.75 | G4: =O4-C4-K4 -> 4251.2206 | H4: =P4-D4-L4 -> 338.97115 | I4: =G4+H4 -> 4590.1917 | K4: ='[2]Consumo Diário'!$DX$42 -> 6649.0374 | L4: ='[2]Consumo Diário'!$DY$42 -> 163.88885 | M4: =K4+L4 -> 6812.9263 | O4: ='[2]Consumo Diário'!$DS$42 -> 138945.56 | P4: ='[2]Consumo Diário'!$DT$42 -> 1541.312 | Q4: =O4+P4 -> 140486.87 | S4: =(E4+I4)/Q4 -> 0.95150489 | T4: =M4/Q4 -> 0.048495111 | V4: =(C4+G4)/Q4 -> 0.94170025 | W4: =(D4+H4)/Q4 -> 0.0098046399 | X4: =K4/Q4 -> 0.047328533 | Y4: =L4/Q4 -> 0.0011665777
B5: 43497 | C5: ='[3]Consumo Diário'!$C$42 -> 117316.54 | D5: ='[3]Consumo Diário'!$D$42 -> 1002.269 | E5: =C5+D5 -> 118318.81 | G5: =O5-C5-K5 -> 4164.4959 | H5: =P5-D5-L5 -> 240.19137 | I5: =G5+H5 -> 4404.6873 | K5: ='[3]Consumo Diário'!$DX$42 -> 5975.6211 | L5: ='[3]Consumo Diário'!$DY$42 -> 211.75563 | M5: =K5+L5 -> 6187.3767 | O5: ='[3]Consumo Diário'!$DS$42 -> 127456.66 | P5: ='[3]Consumo Diário'!$DT$42 -> 1454.216 | Q5: =O5+P5 -> 128910.87 | S5: =(E5+I5)/Q5 -> 0.95200268 | T5: =M5/Q5 -> 0.047997322 | V5: =(C5+G5)/Q5 -> 0.94236454 | W5: =(D5+H5)/Q5 -> 0.0096381347 | X5: =K5/Q5 -> 0.04635467 | Y5: =L5/Q5 -> 0.0016426514
B6: 43525 | C6: ='[4]Consumo Diário'!$C$42 -> 130503.71 | D6: ='[4]Consumo Diário'!$D$42 -> 955.99 | E6: =C6+D6 -> 131459.7 | G6: =O6-C6-K6 -> 4776.9969 | H6: =P6-D6-L6 -> 204.1474 | I6: =G6+H6 -> 4981.1443 | K6: ='[4]Consumo Diário'!$DX$42 -> 6735.3501 | L6: ='[4]Consumo Diário'!$DY$42 -> 269.4556 | M6: =K6+L6 -> 7004.8057 | O6: ='[4]Consumo Diário'!$DS$42 -> 142016.06 | P6: ='[4]Consumo Diário'!$DT$42 -> 1429.593 | Q6: =O6+P6 -> 143445.65 | S6: =(E6+I6)/Q6 -> 0.95116753 | T6: =M6/Q6 -> 0.048832472 | V6: =(C6+G6)/Q6 -> 0.94307988 | W6: =(D6+H6)/Q6 -> 0.0080876443 | X6: =K6/Q6 -> 0.046954021 | Y6: =L6/Q6 -> 0.0018784508
B7: 43556 | C7: ='[5]Consumo Diário'!$C$42 -> 126449.83 | D7: ='[5]Consumo Diário'!$D$42 -> 1016.962 | E7: =C7+D7 -> 127466.79 | G7: =O7-C7-K7 -> 5057.7774 | H7: =P7-D7-L7 -> 254.58675 | I7: =G7+H7 -> 5312.3642 | K7: ='[5]Consumo Diário'!$DX$42 -> 6441.9156 | L7: ='[5]Consumo Diário'!$DY$42 -> 265.04825 | M7: =K7+L7 -> 6706.9638 | O7: ='[5]Consumo Diário'!$DS$42 -> 137949.52 | P7: ='[5]Consumo Diário'!$DT$42 -> 1536.597 | Q7: =O7+P7 -> 139486.12 | S7: =(E7+I7)/Q7 -> 0.95191662 | T7: =M7/Q7 -> 0.048083379 | V7: =(C7+G7)/Q7 -> 0.94280067 | W7: =(D7+H7)/Q7 -> 0.009115952 | X7: =K7/Q7 -> 0.046183202 | Y7: =L7/Q7 -> 0.0019001765
B8: 43586 | C8: ='[6]Consumo Diário'!$C$42 -> 128349.51 | D8: ='[6]Consumo Diário'!$D$42 -> 1006.995 | E8: =C8+D8 -> 129356.5 | G8: =O8-C8-K8 -> 5059.0495 | H8: =P8-D8-L8 -> 241.33126 | I8: =G8+H8 -> 5300.3808 | K8: ='[6]Consumo Diário'!$DX$42 -> 5845.8615 | L8: ='[6]Consumo Diário'!$DY$42 -> 249.47074 | M8: =K8+L8 -> 6095.3322 | O8: ='[6]Consumo Diário'!$DS$42 -> 139254.42 | P8: ='[6]Consumo Diário'!$DT$42 -> 1497.797 | Q8: =O8+P8 -> 140752.21 | S8: =(E8+I8)/Q8 -> 0.95669459 | T8: =M8/Q8 -> 0.043305409 | V8: =(C8+G8)/Q8 -> 0.94782563 | W8: =(D8+H8)/Q8 -> 0.0088689637 | X8: =K8/Q8 -> 0.041532999 | Y8: =L8/Q8 -> 0.0017724108
B9: 43617 | C9: ='[7]Consumo Diário'!$C$42 -> 102197.69 | D9: ='[7]Consumo Diário'!$D$42 -> 902.189 | E9: =C9+D9 -> 103099.88 | G9: =O9-C9-K9 -> 4162.7027 | H9: =P9-D9-L9 -> 238.21771 | I9: =G9+H9 -> 4400.9204 | K9: ='[7]Consumo Diário'!$DX$42 -> 6155.3413 | L9: ='[7]Consumo Diário'!$DY$42 -> 241.31429 | M9: =K9+L9 -> 6396.6556 | O9: ='[7]Consumo Diário'!$DS$42 -> 112515.73 | P9: ='[7]Consumo Diário'!$DT$42 -> 1381.721 | Q9: =O9+P9 -> 113897.46 | S9: =(E9+I9)/Q9 -> 0.94383847 | T9: =M9/Q9 -> 0.056161532 | V9: =(C9+G9)/Q9 -> 0.93382589 | W9: =(D9+H9)/Q9 -> 0.010012574 | X9: =K9/Q9 -> 0.054042834 | Y9: =L9/Q9 -> 0.0021186978
B10: 43647 | C10: ='[8]Consumo Diário'!$C$42 -> 91509.02 | D10: ='[8]Consumo Diário'!$D$42 -> 1139.96 | E10: =C10+D10 -> 92648.98 | G10: =O10-C10-K10 -> 4034.2526 | H10: =P10-D10-L10 -> 294.59516 | I10: =G10+H10 -> 4328.8477 | K10: ='[8]Consumo Diário'!$DX$42 -> 5707.7444 | L10: ='[8]Consumo Diário'!$DY$42 -> 281.91484 | M10: =K10+L10 -> 5989.6593 | O10: ='[8]Consumo Diário'!$DS$42 -> 101251.02 | P10: ='[8]Consumo Diário'!$DT$42 -> 1716.47 | Q10: =O10+P10 -> 102967.49 | S10: =(E10+I10)/Q10 -> 0.94182961 | T10: =M10/Q10 -> 0.058170394 | V10: =(C10+G10)/Q10 -> 0.92789749 | W10: =(D10+H10)/Q10 -> 0.013932118 | X10: =K10/Q10 -> 0.055432492 | Y10: =L10/Q10 -> 0.0027379015
B11: 43678 | C11: ='[9]Consumo Diário'!$C$42 -> 91402.032 | D11: ='[9]Consumo Diário'!$D$42 -> 1125.498 | E11: =C11+D11 -> 92527.53 | G11: =O11-C11-K11 -> 3977.6534 | H11: =P11-D11-L11 -> 263.3656 | I11: =G11+H11 -> 4241.019 | K11: ='[9]Consumo Diário'!$DX$42 -> 5616.7726 | L11: ='[9]Consumo Diário'!$DY$42 -> 267.5464 | M11: =K11+L11 -> 5884.319 | O11: ='[9]Consumo Diário'!$DS$42 -> 100996.46 | P11: ='[9]Consumo Diário'!$DT$42 -> 1656.41 | Q11: =O11+P11 -> 102652.87 | S11: =(E11+I11)/Q11 -> 0.9426775 | T11: =M11/Q11 -> 0.0573225 | V11: =(C11+G11)/Q11 -> 0.92914779 | W11: =(D11+H11)/Q11 -> 0.013529711 | X11: =K11/Q11 -> 0.054716178 | Y11: =L11/Q11 -> 0.0026063217
B12: 43709 | C12: ='[10]Consumo Diário'!$C$42 -> 88616.604 | D12: ='[10]Consumo Diário'!$D$42 -> 1006.646 | E12: =C12+D12 -> 89623.25 | G12: =O12-C12-K12 -> 3964.7494 | H12: =P12-D12-L12 -> 260.5902 | I12: =G12+H12 -> 4225.3396 | K12: ='[10]Consumo Diário'!$DX$42 -> 5364.5346 | L12: ='[10]Consumo Diário'!$DY$42 -> 238.1908 | M12: =K12+L12 -> 5602.7254 | O12: ='[10]Consumo Diário'!$DS$42 -> 97945.888 | P12: ='[10]Consumo Diário'!$DT$42 -> 1505.427 | Q12: =O12+P12 -> 99451.315 | S12: =(E12+I12)/Q12 -> 0.94366364 | T12: =M12/Q12 -> 0.056336363 | V12: =(C12+G12)/Q12 -> 0.93092136 | W12: =(D12+H12)/Q12 -> 0.012742277 | X12: =K12/Q12 -> 0.053941314 | Y12: =L12/Q12 -> 0.0023950493
B13: 43739 | C13: ='[11]Consumo Diário'!$C$42 -> 92023.942 | D13: ='[11]Consumo Diário'!$D$42 -> 1226.168 | E13: =C13+D13 -> 93250.11 | G13: =O13-C13-K13 -> 3226.0329 | H13: =P13-D13-L13 -> 199.449 | I13: =G13+H13 -> 3425.4819 | K13: ='[11]Consumo Diário'!$DT$42 -> 5718.3921 | L13: ='[11]Consumo Diário'!$DU$42 -> 287.734 | M13: =K13+L13 -> 6006.1261 | O13: ='[11]Consumo Diário'!$DO$42 -> 100968.37 | P13: ='[11]Consumo Diário'!$DP$42 -> 1713.351 | Q13: =O13+P13 -> 102681.72 | S13: =(E13+I13)/Q13 -> 0.94150735 | T13: =M13/Q13 -> 0.058492653 | V13: =(C13+G13)/Q13 -> 0.9276235 | W13: =(D13+H13)/Q13 -> 0.013883844 | X13: =K13/Q13 -> 0.05569046 | Y13: =L13/Q13 -> 0.0028021931
B14: 43770 | C14: ='[12]Consumo Diário'!$C$42 -> 94358.725 | D14: ='[12]Consumo Diário'!$D$42 -> 1006.117 | E14: =C14+D14 -> 95364.842 | G14: =O14-C14-K14 -> 3695.702 | H14: =P14-D14-L14 -> 204.4586 | I14: =G14+H14 -> 3900.1606 | K14: ='[12]Consumo Diário'!$DT$42 -> 5397.622 | L14: ='[12]Consumo Diário'!$DU$42 -> 243.5204 | M14: =K14+L14 -> 5641.1424 | O14: ='[12]Consumo Diário'!$DO$42 -> 103452.05 | P14: ='[12]Consumo Diário'!$DP$42 -> 1454.096 | Q14: =O14+P14 -> 104906.15 | S14: =(E14+I14)/Q14 -> 0.94622677 | T14: =M14/Q14 -> 0.053773231 | V14: =(C14+G14)/Q14 -> 0.93468716 | W14: =(D14+H14)/Q14 -> 0.011539606 | X14: =K14/Q14 -> 0.051451914 | Y14: =L14/Q14 -> 0.0023213168
B15: 43800 | C15: ='[13]Consumo Diário'!$C$42 -> 125856.38 | D15: ='[13]Consumo Diário'!$D$42 -> 948.05 | E15: =C15+D15 -> 126804.43 | G15: =O15-C15-K15 -> 4804.4613 | H15: =P15-D15-L15 -> 306.7694 | I15: =G15+H15 -> 5111.2307 | K15: ='[13]Consumo Diário'!$DT$42 -> 6743.4747 | L15: ='[13]Consumo Diário'!$DU$42 -> 295.4246 | M15: =K15+L15 -> 7038.8993 | O15: ='[13]Consumo Diário'!$DO$42 -> 137404.32 | P15: ='[13]Consumo Diário'!$DP$42 -> 1550.244 | Q15: =O15+P15 -> 138954.56 | S15: =(E15+I15)/Q15 -> 0.94934388 | T15: =M15/Q15 -> 0.050656123 | V15: =(C15+G15)/Q15 -> 0.94031345 | W15: =(D15+H15)/Q15 -> 0.0090304299 | X15: =K15/Q15 -> 0.048530072 | Y15: =L15/Q15 -> 0.0021260519
B16: 43831 | C16: ='[14]Consumo Diário'!$C$42 -> 126534.03 | D16: ='[14]Consumo Diário'!$D$42 -> 1003.668 | E16: =C16+D16 -> 127537.69 | G16: =O16-C16-K16 -> 4892.1756 | H16: =P16-D16-L16 -> 294.8714 | I16: =G16+H16 -> 5187.047 | K16: ='[14]Consumo Diário'!$DT$42 -> 6989.1944 | L16: ='[14]Consumo Diário'!$DU$42 -> 293.5456 | M16: =K16+L16 -> 7282.74 | O16: ='[14]Consumo Diário'!$DO$42 -> 138415.4 | P16: ='[14]Consumo Diário'!$DP$42 -> 1592.085 | Q16: =O16+P16 -> 140007.48 | S16: =(E16+I16)/Q16 -> 0.94798321 | T16: =M16/Q16 -> 0.052016792 | V16: =(C16+G16)/Q16 -> 0.93870842 | W16: =(D16+H16)/Q16 -> 0.0092747858 | X16: =K16/Q16 -> 0.04992015 | Y16: =L16/Q16 -> 0.0020966423
B17: 43862 | C17: ='[14]Consumo Diário'!$C$42 -> 126534.03 | D17: ='[14]Consumo Diário'!$D$42 -> 1003.668 | E17: =C17+D17 -> 127537.69 | G17: =O17-C17-K17 -> 1747.0056 | H17: =P17-D17-L17 -> 103.4764 | I17: =G17+H17 -> 1850.482 | K17: ='[14]Consumo Diário'!$DT$42 -> 6989.1944 | L17: ='[14]Consumo Diário'!$DU$42 -> 293.5456 | M17: =K17+L17 -> 7282.74 | O17: ='[15]Consumo Diário'!$DN$42 -> 135270.23 | P17: ='[15]Consumo Diário'!$DO$42 -> 1400.69 | Q17: =O17+P17 -> 136670.92 | S17: =(E17+I17)/Q17 -> 0.94671332 | T17: =M17/Q17 -> 0.053286685 | V17: =(C17+G17)/Q17 -> 0.93861251 | W17: =(D17+H17)/Q17 -> 0.0081008047 | X17: =K17/Q17 -> 0.051138857 | Y17: =L17/Q17 -> 0.0021478279
B18: 43891 | C18: ='[15]Consumo Diário'!$C$42 -> 124104.38 | D18: ='[15]Consumo Diário'!$D$42 -> 891.38 | E18: =C18+D18 -> 124995.76 | G18: =O18-C18-K18 -> 10504.428 | H18: =P18-D18-L18 -> 465.1356 | I18: =G18+H18 -> 10969.563 | K18: ='[15]Consumo Diário'!$DS$42 -> 6540.3074 | L18: ='[15]Consumo Diário'!$DT$42 -> 261.8614 | M18: =K18+L18 -> 6802.1688 | O18: ='[16]Consumo Diário'!$ED$42 -> 141149.12 | P18: ='[16]Consumo Diário'!$EE$42 -> 1618.377 | Q18: =O18+P18 -> 142767.5 | S18: =(E18+I18)/Q18 -> 0.95235492 | T18: =M18/Q18 -> 0.04764508 | V18: =(C18+G18)/Q18 -> 0.94285335 | W18: =(D18+H18)/Q18 -> 0.0095015717 | X18: =K18/Q18 -> 0.045810899 | Y18: =L18/Q18 -> 0.0018341808
B19: 43922 | C19: ='[16]Consumo Diário'!$C$42 -> 129409.29 | D19: ='[16]Consumo Diário'!$D$42 -> 1008.75 | E19: =C19+D19 -> 130418.04 | G19: =O19-C19-K19 -> 7294.4596 | H19: =P19-D19-L19 -> 303.34354 | I19: =G19+H19 -> 7597.8031 | K19: ='[16]Consumo Diário'!$EI$42 -> 6895.1214 | L19: ='[16]Consumo Diário'!$EJ$42 -> 306.28346 | M19: =K19+L19 -> 7201.4049 | O19: ='[17]Consumo Diário'!$ED$42 -> 143598.87 | P19: ='[16]Consumo Diário'!$EE$42 -> 1618.377 | Q19: =O19+P19 -> 145217.25 | S19: =(E19+I19)/Q19 -> 0.95040944 | T19: =M19/Q19 -> 0.049590563 | V19: =(C19+G19)/Q19 -> 0.94137405 | W19: =(D19+H19)/Q19 -> 0.0090353838 | X19: =K19/Q19 -> 0.047481423 | Y19: =L19/Q19 -> 0.0021091397
B20: 43952 | C20: ='[18]Consumo Diário'!$C$42 -> 137360.64 | D20: ='[18]Consumo Diário'!$D$42 -> 950.994 | E20: =C20+D20 -> 138311.64 | G20: =O20-C20-K20 -> 4897.5224 | H20: =P20-D20-L20 -> 261.48373 | I20: =G20+H20 -> 5159.0062 | K20: ='[18]Consumo Diário'!$EI$42 -> 6856.1426 | L20: ='[18]Consumo Diário'!$EJ$42 -> 290.46927 | M20: =K20+L20 -> 7146.6118 | O20: ='[18]Consumo Diário'!$ED$42 -> 149114.31 | P20: ='[18]Consumo Diário'!$EE$42 -> 1502.947 | Q20: =O20+P20 -> 150617.26 | S20: =(E20+I20)/Q20 -> 0.95255117 | T20: =M20/Q20 -> 0.047448825 | V20: =(C20+G20)/Q20 -> 0.94450112 | W20: =(D20+H20)/Q20 -> 0.0080500586 | X20: =K20/Q20 -> 0.0455203 | Y20: =L20/Q20 -> 0.0019285258
B21: 43983 | C21: ='[19]Consumo Diário'!$C$42 -> 132342.08 | D21: ='[19]Consumo Diário'!$D$42 -> 961.615 | E21: =C21+D21 -> 133303.69 | G21: =O21-C21-K21 -> 4988.1318 | H21: =P21-D21-L21 -> 309.07096 | I21: =G21+H21 -> 5297.2027 | K21: ='[19]Consumo Diário'!$EI$42 -> 6473.5532 | L21: ='[19]Consumo Diário'!$EJ$42 -> 297.53504 | M21: =K21+L21 -> 6771.0883 | O21: ='[19]Consumo Diário'!$ED$42 -> 143803.76 | P21: ='[19]Consumo Diário'!$EE$42 -> 1568.221 | Q21: =O21+P21 -> 145371.99 | S21: =(E21+I21)/Q21 -> 0.95342233 | T21: =M21/Q21 -> 0.046577669 | V21: =(C21+G21)/Q21 -> 0.9446814 | W21: =(D21+H21)/Q21 -> 0.0087409274 | X21: =K21/Q21 -> 0.044530954 | Y21: =L21/Q21 -> 0.0020467151
B22: 44013 | C22: ='[20]Consumo Diário'!$C$42 -> 136582.73 | D22: ='[20]Consumo Diário'!$D$42 -> 1046.4179 | E22: =C22+D22 -> 137629.15 | G22: =O22-C22-K22 -> 4923.4702 | H22: =P22-D22-L22 -> 315.10317 | I22: =G22+H22 -> 5238.5733 | K22: ='[20]Consumo Diário'!$EI$42 -> 6750.2004 | L22: ='[20]Consumo Diário'!$EJ$42 -> 350.86093 | M22: =K22+L22 -> 7101.0614 | O22: ='[20]Consumo Diário'!$ED$42 -> 148256.4 | P22: ='[20]Consumo Diário'!$EE$42 -> 1712.382 | Q22: =O22+P22 -> 149968.78 | S22: =(E22+I22)/Q22 -> 0.95264974 | T22: =M22/Q22 -> 0.047350264 | V22: =(C22+G22)/Q22 -> 0.94357104 | W22: =(D22+H22)/Q22 -> 0.0090786967 | X22: =K22/Q22 -> 0.045010704 | Y22: =L22/Q22 -> 0.0023395598
B23: 44044 | C23: ='[21]Consumo Diário'!$C$42 -> 139258.68 | D23: ='[21]Consumo Diário'!$D$42 -> 1017.025 | E23: =C23+D23 -> 140275.7 | G23: =O23-C23-K23 -> 4943.6309 | H23: =P23-D23-L23 -> 284.3839 | I23: =G23+H23 -> 5228.0148 | K23: ='[21]Consumo Diário'!$EI$42 -> 7040.4301 | L23: ='[21]Consumo Diário'!$EJ$42 -> 281.9441 | M23: =K23+L23 -> 7322.3742 | O23: ='[21]Consumo Diário'!$ED$42 -> 151242.74 | P23: ='[21]Consumo Diário'!$EE$42 -> 1583.353 | Q23: =O23+P23 -> 152826.09 | S23: =(E23+I23)/Q23 -> 0.95208689 | T23: =M23/Q23 -> 0.047913115 | V23: =(C23+G23)/Q23 -> 0.94357127 | W23: =(D23+H23)/Q23 -> 0.0085156197 | X23: =K23/Q23 -> 0.046068246 | Y23: =L23/Q23 -> 0.0018448688
B24: 44075 | C24: 130047.23 | D24: 1037.209 | E24: =C24+D24 -> 131084.44 | G24: =O24-C24-K24 -> 4692.3854 | H24: =P24-D24-L24 -> 285.72194 | I24: =G24+H24 -> 4978.1073 | K24: 6644.4096 | L24: 266.65506 | M24: =K24+L24 -> 6911.0647 | O24: 141384.02 | P24: 1589.586 | Q24: =O24+P24 -> 142973.61 | S24: =(E24+I24)/Q24 -> 0.95166196 | T24: =M24/Q24 -> 0.048338045 | V24: =(C24+G24)/Q24 -> 0.94240898 | W24: =(D24+H24)/Q24 -> 0.009252973 | X24: =K24/Q24 -> 0.04647298 | Y24: =L24/Q24 -> 0.0018650649
B25: 44105 | C25: 131971.47 | D25: 959.069 | E25: =C25+D25 -> 132930.53 | G25: =O25-C25-K25 -> 5206.2974 | H25: =P25-D25-L25 -> 280.57778 | I25: =G25+H25 -> 5486.8751 | K25: 6886.7356 | L25: 308.77722 | M25: =K25+L25 -> 7195.5129 | O25: 144064.5 | P25: 1548.424 | Q25: =O25+P25 -> 145612.92 | S25: =(E25+I25)/Q25 -> 0.95058465 | T25: =M25/Q25 -> 0.049415346 | V25: =(C25+G25)/Q25 -> 0.94207135 | W25: =(D25+H25)/Q25 -> 0.008513302 | X25: =K25/Q25 -> 0.047294811 | Y25: =L25/Q25 -> 0.0021205345
B26: 44136 | C26: 105349.79 | D26: 903.231 | E26: =C26+D26 -> 106253.02 | G26: =O26-C26-K26 -> 3976.5511 | H26: =P26-D26-L26 -> 280.28073 | I26: =G26+H26 -> 4256.8318 | K26: 5328.8666 | L26: 259.90827 | M26: =K26+L26 -> 5588.7749 | O26: 114655.2 | P26: 1443.42 | Q26: =O26+P26 -> 116098.62 | S26: =(E26+I26)/Q26 -> 0.95186183 | T26: =M26/Q26 -> 0.048138167 | V26: =(C26+G26)/Q26 -> 0.94166781 | W26: =(D26+H26)/Q26 -> 0.01019402 | X26: =K26/Q26 -> 0.045899482 | Y26: =L26/Q26 -> 0.0022386852
B27: 44166 | C27: 134346.26 | D27: 1021.576 | E27: =C27+D27 -> 135367.83 | G27: =O27-C27-K27 -> 4945.3745 | H27: =P27-D27-L27 -> 273.81942 | I27: =G27+H27 -> 5219.1939 | K27: 6782.3414 | L27: 295.96458 | M27: =K27+L27 -> 7078.306 | O27: 146073.97 | P27: 1591.36 | Q27: =O27+P27 -> 147665.33 | S27: =(E27+I27)/Q27 -> 0.95206522 | T27: =M27/Q27 -> 0.047934785 | V27: =(C27+G27)/Q27 -> 0.94329271 | W27: =(D27+H27)/Q27 -> 0.0087725087 | X27: =K27/Q27 -> 0.045930492 | Y27: =L27/Q27 -> 0.0020042929
B28: 44197 | C28: 136708.42 | D28: 933.0493 | E28: =C28+D28 -> 137641.46 | G28: =O28-C28-K28 -> 4967.805 | H28: =P28-D28-L28 -> 252.57243 | I28: =G28+H28 -> 5220.3775 | K28: 6982.6417 | L28: 300.43627 | M28: =K28+L28 -> 7283.0779 | O28: 148658.86 | P28: 1486.058 | Q28: =O28+P28 -> 150144.92 | S28: =(E28+I28)/Q28 -> 0.95149301 | T28: =M28/Q28 -> 0.048506989 | V28: =(C28+G28)/Q28 -> 0.9435965 | W28: =(D28+H28)/Q28 -> 0.0078965158 | X28: =K28/Q28 -> 0.046506013 | Y28: =L28/Q28 -> 0.0020009753
B29: 44228 | C29: 121541.18 | D29: 849.9355 | E29: =C29+D29 -> 122391.12 | G29: =O29-C29-K29 -> 4592.6935 | H29: =P29-D29-L29 -> 255.72467 | I29: =G29+H29 -> 4848.4182 | K29: 6289.7639 | L29: 287.29583 | M29: =K29+L29 -> 6577.0597 | O29: 132423.64 | P29: 1392.956 | Q29: =O29+P29 -> 133816.59 | S29: =(E29+I29)/Q29 -> 0.95085019 | T29: =M29/Q29 -> 0.049149807 | V29: =(C29+G29)/Q29 -> 0.94258769 | W29: =(D29+H29)/Q29 -> 0.0082625042 | X29: =K29/Q29 -> 0.047002869 | Y29: =L29/Q29 -> 0.0021469372
B30: 44256 | C30: 139845.57 | D30: 977.9499 | E30: =C30+D30 -> 140823.52 | G30: =O30-C30-K30 -> 5056.7823 | H30: =P30-D30-L30 -> 308.69939 | I30: =G30+H30 -> 5365.4817 | K30: 6941.3565 | L30: 339.79071 | M30: =K30+L30 -> 7281.1472 | O30: 151843.71 | P30: 1626.44 | Q30: =O30+P30 -> 153470.15 | S30: =(E30+I30)/Q30 -> 0.95255659 | T30: =M30/Q30 -> 0.04744341 | V30: =(C30+G30)/Q30 -> 0.94417288 | W30: =(D30+H30)/Q30 -> 0.0083837104 | X30: =K30/Q30 -> 0.045229359 | Y30: =L30/Q30 -> 0.0022140509
B31: 44287 | C31: 133727.98 | D31: 844.8968 | E31: =C31+D31 -> 134572.87 | G31: =O31-C31-K31 -> 4793.3791 | H31: =P31-D31-L31 -> 262.06845 | I31: =G31+H31 -> 5055.4476 | K31: 6537.5212 | L31: 285.99275 | M31: =K31+L31 -> 6823.5139 | O31: 145058.88 | P31: 1392.958 | Q31: =O31+P31 -> 146451.84 | S31: =(E31+I31)/Q31 -> 0.9534078 | T31: =M31/Q31 -> 0.046592205 | V31: =(C31+G31)/Q31 -> 0.94584923 | W31: =(D31+H31)/Q31 -> 0.0075585618 | X31: =K31/Q31 -> 0.044639394 | Y31: =L31/Q31 -> 0.001952811
B32: 44317 | C32: 140733.49 | D32: 955.1982 | E32: =C32+D32 -> 141688.69 | G32: =O32-C32-K32 -> 4828.9359 | H32: =P32-D32-L32 -> 274.88061 | I32: =G32+H32 -> 5103.8165 | K32: 6828.5203 | L32: 322.96019 | M32: =K32+L32 -> 7151.4805 | O32: 152390.95 | P32: 1553.039 | Q32: =O32+P32 -> 153943.99 | S32: =(E32+I32)/Q32 -> 0.95354492 | T32: =M32/Q32 -> 0.046455081 | V32: =(C32+G32)/Q32 -> 0.94555449 | W32: =(D32+H32)/Q32 -> 0.0079904309 | X32: =K32/Q32 -> 0.044357173 | Y32: =L32/Q32 -> 0.0020979071
B33: 44348 | C33: 121078.1 | D33: 948.3736 | E33: =C33+D33 -> 122026.47 | G33: =O33-C33-K33 -> 4382.9937 | H33: =P33-D33-L33 -> 283.04309 | I33: =G33+H33 -> 4666.0368 | K33: 6240.7079 | L33: 323.10431 | M33: =K33+L33 -> 6563.8122 | O33: 131701.8 | P33: 1554.521 | Q33: =O33+P33 -> 133256.32 | S33: =(E33+I33)/Q33 -> 0.95074296 | T33: =M33/Q33 -> 0.049257041 | V33: =(C33+G33)/Q33 -> 0.941502 | W33: =(D33+H33)/Q33 -> 0.0092409625 | X33: =K33/Q33 -> 0.046832359 | Y33: =L33/Q33 -> 0.0024246828
B34: 44378 | C34: 139929.78 | D34: 968.3854 | E34: =C34+D34 -> 140898.17 | G34: =O34-C34-K34 -> 5005.9059 | H34: =P34-D34-L34 -> 303.02506 | I34: =G34+H34 -> 5308.931 | K34: 6769.8177 | L34: 354.57654 | M34: =K34+L34 -> 7124.3942 | O34: 151705.51 | P34: 1625.987 | Q34: =O34+P34 -> 153331.49 | S34: =(E34+I34)/Q34 -> 0.953536 | T34: =M34/Q34 -> 0.046463999 | V34: =(C34+G34)/Q34 -> 0.94524409 | W34: =(D34+H34)/Q34 -> 0.0082919069 | X34: =K34/Q34 -> 0.044151515 | Y34: =L34/Q34 -> 0.0023124835
B35: 44409 | C35: 142073.76 | D35: 979.4797 | E35: =C35+D35 -> 143053.24 | G35: =O35-C35-K35 -> 5281.6308 | H35: =P35-D35-L35 -> 301.75567 | I35: =G35+H35 -> 5583.3864 | K35: 6886.3397 | L35: 364.91163 | M35: =K35+L35 -> 7251.2514 | O35: 154241.73 | P35: 1646.147 | Q35: =O35+P35 -> 155887.88 | S35: =(E35+I35)/Q35 -> 0.95348419 | T35: =M35/Q35 -> 0.046515812 | V35: =(C35+G35)/Q35 -> 0.94526523 | W35: =(D35+H35)/Q35 -> 0.0082189543 | X35: =K35/Q35 -> 0.044174952 | Y35: =L35/Q35 -> 0.0023408595
B36: 44440 | C36: 137045.2 | D36: 928.7554 | E36: =C36+D36 -> 137973.96 | G36: =4355.1715+937.7245 -> 5292.896 | H36: =186.2257+89.8605 -> 276.0862 | I36: =G36+H36 -> 5568.9822 | K36: 6646.6646 | L36: 324.2812 | M36: =K36+L36 -> 6970.9458 | O36: 148979.38 | P36: 1541.994 | Q36: =O36+P36 -> 150521.37 | S36: =(E36+I36)/Q36 -> 0.95363825 | T36: =M36/Q36 -> 0.046312 | V36: =(C36+G36)/Q36 -> 0.9456338 | W36: =(D36+H36)/Q36 -> 0.0080044553 | X36: =K36/Q36 -> 0.044157614 | Y36: =L36/Q36 -> 0.0021543864
B37: 44470 | C37: 141694.61 | D37: 858.2874 | E37: =C37+D37 -> 142552.9 | G37: =4734.6159+918.8488 -> 5653.4647 | H37: =195.6931+80.9342 -> 276.6273 | I37: =G37+H37 -> 5930.092 | K37: 6816.5336 | L37: 328.3873 | M37: =K37+L37 -> 7144.9209 | O37: 154159.17 | P37: 1463.138 | Q37: =O37+P37 -> 155622.3 | S37: =(E37+I37)/Q37 -> 0.9541241 | T37: =M37/Q37 -> 0.045911933 | V37: =(C37+G37)/Q37 -> 0.94683135 | W37: =(D37+H37)/Q37 -> 0.0072927509 | X37: =K37/Q37 -> 0.043801778 | Y37: =L37/Q37 -> 0.0021101557
B38: 44501 | C38: ='[22]Consumo Diário'!$C$42 -> 136942.6 | D38: ='[22]Consumo Diário'!$D$42 -> 864.0848 | E38: =C38+D38 -> 137806.69 | G38: =O38-C38-K38 -> 5158.9242 | H38: =P38-D38-L38 -> 276.65422 | I38: =G38+H38 -> 5435.5785 | K38: ='[22]Consumo Diário'!$EI$42 -> 6599.6263 | L38: ='[22]Consumo Diário'!$EJ$42 -> 292.52498 | M38: =K38+L38 -> 6892.1512 | O38: ='[22]Consumo Diário'!$ED$42 -> 148701.15 | P38: ='[22]Consumo Diário'!$EE$42 -> 1433.264 | Q38: =O38+P38 -> 150134.42 | S38: =(E38+I38)/Q38 -> 0.95409346 | T38: =M38/Q38 -> 0.045906538 | V38: =(C38+G38)/Q38 -> 0.94649534 | W38: =(D38+H38)/Q38 -> 0.007598118 | X38: =K38/Q38 -> 0.043958117 | Y38: =L38/Q38 -> 0.0019484206
B39: 44531 | C39: ='[23]Consumo Diário'!$C$42 -> 140433.22 | D39: ='[23]Consumo Diário'!$D$42 -> 1027.0577 | E39: =C39+D39 -> 141460.28 | G39: =O39-C39-K39 -> 5268.354 | H39: =P39-D39-L39 -> 294.22209 | I39: =G39+H39 -> 5562.576 | K39: ='[23]Consumo Diário'!$EI$42 -> 7027.6148 | L39: ='[23]Consumo Diário'!$EJ$42 -> 352.98321 | M39: =K39+L39 -> 7380.5981 | O39: ='[23]Consumo Diário'!$ED$42 -> 152729.19 | P39: ='[23]Consumo Diário'!$EE$42 -> 1674.263 | Q39: =O39+P39 -> 154403.45 | S39: =(E39+I39)/Q39 -> 0.95219927 | T39: =M39/Q39 -> 0.047800733 | V39: =(C39+G39)/Q39 -> 0.94364195 | W39: =(D39+H39)/Q39 -> 0.0085573204 | X39: =K39/Q39 -> 0.045514623 | Y39: =L39/Q39 -> 0.0022861096
B40: 44562 | C40: ='[24]Consumo Diário'!$C$42 -> 137269.28 | D40: ='[24]Consumo Diário'!$D$42 -> 933.5832 | E40: =C40+D40 -> 138202.86 | G40: =O40-C40-K40 -> 5242.8355 | H40: =P40-D40-L40 -> 287.55232 | I40: =G40+H40 -> 5530.3878 | K40: ='[24]Consumo Diário'!$EI$42 -> 7160.483 | L40: ='[24]Consumo Diário'!$EJ$42 -> 344.09248 | M40: =K40+L40 -> 7504.5755 | O40: ='[24]Consumo Diário'!$ED$42 -> 149672.6 | P40: ='[24]Consumo Diário'!$EE$42 -> 1565.228 | Q40: =O40+P40 -> 151237.83 | S40: =(E40+I40)/Q40 -> 0.95037898 | T40: =M40/Q40 -> 0.049621022 | V40: =(C40+G40)/Q40 -> 0.9423047 | W40: =(D40+H40)/Q40 -> 0.0080742732 | X40: =K40/Q40 -> 0.047345847 | Y40: =L40/Q40 -> 0.0022751747
B41: 44593 | C41: ='[25]Consumo Diário'!$C$42 -> 127696.46 | D41: ='[25]Consumo Diário'!$D$42 -> 847.3136 | E41: =C41+D41 -> 128543.78 | G41: =O41-C41-K41 -> 4730.5633 | H41: =P41-D41-L41 -> 280.64253 | I41: =G41+H41 -> 5011.2058 | K41: ='[25]Consumo Diário'!$EI$42 -> 6280.5941 | L41: ='[25]Consumo Diário'!$EJ$42 -> 365.58287 | M41: =K41+L41 -> 6646.177 | O41: ='[25]Consumo Diário'!$ED$42 -> 138707.62 | P41: ='[25]Consumo Diário'!$EE$42 -> 1493.539 | Q41: =O41+P41 -> 140201.16 | S41: =(E41+I41)/Q41 -> 0.95259542 | T41: =M41/Q41 -> 0.047404579 | V41: =(C41+G41)/Q41 -> 0.94455015 | W41: =(D41+H41)/Q41 -> 0.0080452696 | X41: =K41/Q41 -> 0.04479702 | Y41: =L41/Q41 -> 0.0026075595
B42: 44621 | C42: ='[26]Consumo Diário'!$C$42 -> 138476.43 | D42: ='[26]Consumo Diário'!$D$42 -> 984.5133 | E42: =C42+D42 -> 139460.94 | G42: =O42-C42-K42 -> 5280.3864 | H42: =P42-D42-L42 -> 312.76599 | I42: =G42+H42 -> 5593.1523 | K42: ='[26]Consumo Diário'!$EI$42 -> 7054.6794 | L42: ='[26]Consumo Diário'!$EJ$42 -> 379.72671 | M42: =K42+L42 -> 7434.4062 | O42: ='[26]Consumo Diário'!$ED$42 -> 150811.49 | P42: ='[26]Consumo Diário'!$EE$42 -> 1677.006 | Q42: =O42+P42 -> 152488.5 | S42: =(E42+I42)/Q42 -> 0.95124612 | T42: =M42/Q42 -> 0.048753882 | V42: =(C42+G42)/Q42 -> 0.94273873 | W42: =(D42+H42)/Q42 -> 0.0085073911 | X42: =K42/Q42 -> 0.046263683 | Y42: =L42/Q42 -> 0.0024901991
...

Sheet Energia Aux - Min
B2: Mês | C2: JAN | D2: FEV | E2: MAR | F2: ABR | G2: MAI | H2: JUN | I2: JUL | J2: AGO | K2: SET | L2: OUT | M2: NOV | N2: DEZ | Q2: Consumo Histórico Ipueira
B3: Contrato | C3: 5 | D3: 5 | E3: 5 | F3: 5 | G3: 5 | H3: 5 | I3: 5 | J3: 5 | K3: 5 | L3: 5 | M3: 5 | N3: 5 | P3: 44562 | Q3: ='[41]Volume de Energia (1)'!$K$16+'[41]Volume de Energia (1)'!$K$17 -> 3331.33
B4: Horas | C4: 744 | D4: 696 | E4: 744 | F4: 720 | G4: 744 | H4: 720 | I4: 744 | J4: 744 | K4: 720 | L4: 744 | M4: 720 | N4: 744 | P4: 44593 | Q4: ='[42]Volume de Energia (1)'!$K$16+'[42]Volume de Energia (1)'!$K$17 -> 3145.373
B5: Capacidade - MWh | C5: =C4*C3 -> 3720 | D5: =D4*D3 -> 3480 | E5: =E4*E3 -> 3720 | F5: =F4*F3 -> 3600 | G5: =G4*G3 -> 3720 | H5: =H4*H3 -> 3600 | I5: =I4*I3 -> 3720 | J5: =J4*J3 -> 3720 | ... N5: =N4*N3 -> 3720 | P5: 44621 | Q5: ='[43]Volume de Energia (1)'!$K$16+'[43]Volume de Energia (1)'!$K$17 -> 3532.598
B6: Consumo Histórico | C6: =$Q$21 -> 3357.1664 | D6: =$Q$21 -> 3357.1664 | E6: =$Q$21 -> 3357.1664 | F6: =$Q$21 -> 3357.1664 | G6: =$Q$21 -> 3357.1664 | H6: =$Q$21 -> 3357.1664 | I6: =$Q$21 -> 3357.1664 | J6: =$Q$21 -> 3357.1664 | ... N6: =$Q$21 -> 3357.1664 | P6: 44652 | Q6: ='[44]Volume de Energia (1)'!$K$16+'[44]Volume de Energia (1)'!$K$17 -> 3497.858
B7: Perdas | C7: =C6*3% -> 100.71499 | D7: =D6*3% -> 100.71499 | E7: =E6*3% -> 100.71499 | F7: =F6*3% -> 100.71499 | G7: =G6*3% -> 100.71499 | H7: =H6*3% -> 100.71499 | I7: =I6*3% -> 100.71499 | J7: =J6*3% -> 100.71499 | ... N7: =N6*3% -> 100.71499 | P7: 44682 | Q7: ='[45]Volume de Energia (1)'!$K$16+'[45]Volume de Energia (1)'!$K$17 -> 3500.121
P8: 44713 | Q8: ='[46]Volume de Energia (1)'!$K$16+'[46]Volume de Energia (1)'!$K$17 -> 3364.705
B9: Sobras | C9: =C5-(C6+C7) -> 262.11866 | D9: =D5-(D6+D7) -> 22.118656 | E9: =E5-(E6+E7) -> 262.11866 | F9: =F5-(F6+F7) -> 142.11866 | G9: =G5-(G6+G7) -> 262.11866 | H9: =H5-(H6+H7) -> 142.11866 | I9: =I5-(I6+I7) -> 262.11866 | J9: =J5-(J6+J7) -> 262.11866 | ... N9: =N5-(N6+N7) -> 262.11866 | P9: 44743 | Q9: ='[47]Volume de Energia (1)'!$K$16+'[47]Volume de Energia (1)'!$K$17 -> 3293.4392
P10: 44774 | Q10: ='[48]Volume de Energia (1)'!$K$16+'[48]Volume de Energia (1)'!$K$17 -> 3526.8398
B11: Ajuste Energia (Mwmed) | C11: =C6/C4 -> 4.5123204 | D11: =D6/D4 -> 4.8235149 | E11: =E6/E4 -> 4.5123204 | F11: =F6/F4 -> 4.662731 | G11: =G6/G4 -> 4.5123204 | H11: =H6/H4 -> 4.662731 | I11: =I6/I4 -> 4.5123204 | J11: =J6/J4 -> 4.5123204 | ... N11: =N6/N4 -> 4.5123204 | P11: 44805 | Q11: ='[49]Volume de Energia (1)'!$K$16+'[49]Volume de Energia (1)'!$K$17 -> 3252.325
P12: 44835 | Q12: ='[50]Volume de Energia (1)'!$K$16+'[50]Volume de Energia (1)'!$K$17 -> 3370.827
C13: 1T | F13: 2T | I13: 3T | L13: 4T | P13: 44866 | Q13: ='[51]Volume de Energia (1)'!$K$16+'[51]Volume de Energia (1)'!$K$17 -> 3295.638
C14: =SUM(C6:E6)/SUM(C4:E4) -> 4.6114922 | F14: =SUM(F6:H6)/SUM(F4:H4) -> 4.6114922 | I14: =SUM(I6:K6)/SUM(I4:K4) -> 4.5613673 | L14: =SUM(L6:N6)/SUM(L4:N4) -> 4.5613673 | P14: 44896 | Q14: ='[52]Volume de Energia (1)'!$K$16+'[52]Volume de Energia (1)'!$K$17 -> 3311.311
P15: 44927 | Q15: ='[53]Volume de Energia (1)'!$K$16+'[53]Volume de Energia (1)'!$K$17 -> 3246.834
P16: 44958 | Q16: ='[54]Volume de Energia (1)'!$K$16+'[54]Volume de Energia (1)'!$K$17 -> 2943.528
P17: 44986 | Q17: ='[55]Volume de Energia (1)'!$K$16+'[55]Volume de Energia (1)'!$K$17 -> 3553.12
P18: 45017 | Q18: ='[56]Volume de Energia (1)'!$K$16+'[56]Volume de Energia (1)'!$K$17 -> 3300.671
P19: 45047 | Q19: ='[57]Volume de Energia (1)'!$K$16+'[57]Volume de Energia (1)'!$K$17 -> 3605.31
Q21: =AVERAGE(Q3:Q19) -> 3357.1664

Sheet Plan1
D1: 744 | E1: 720 | F1: 744
B2: Volume MWmed | D2: OUT | E2: NOV | F2: DEZ
B3: Metalurgia | C3: CHESF | D3: 90 | E3: 90 | F3: 90
C4: CPFL | D4: 30 | E4: 30 | F4: 30
C5: AES | D5: 80 | E5: 80 | F5: 80
C6: SPOT | D6: 8.6 | E6: 8.6 | F6: 8.6
B7: Mineração | C7: PRIME | D7: 5 | E7: 5 | F7: 5
C8: Neoenergia | D8: 0.9 | E8: 0.9 | F8: 0.9
B11: Volume MWh | D11: OUT | E11: NOV | F11: DEZ
B12: Metalurgia | C12: CHESF | D12: =D3*$D$1 -> 66960 | E12: =E3*$E$1 -> 64800 | F12: =F3*$F$1 -> 66960
C13: CPFL | D13: =D4*$D$1 -> 22320 | E13: =E4*$E$1 -> 21600 | F13: =F4*$F$1 -> 22320
C14: AES | D14: =D5*$D$1 -> 59520 | E14: =E5*$E$1 -> 57600 | F14: =F5*$F$1 -> 59520
C15: SPOT | D15: =D6*$D$1 -> 6398.4 | E15: =E6*$E$1 -> 6192 | F15: =F6*$F$1 -> 6398.4
B16: Mineração | C16: PRIME | D16: =D7*$D$1 -> 3720 | E16: =E7*$E$1 -> 3600 | F16: =F7*$F$1 -> 3720
C17: Neoenergia | D17: =D8*$D$1 -> 669.6 | E17: =E8*$E$1 -> 648 | F17: =F8*$F$1 -> 669.6
B20: Preço R$/MWh | D20: OUT | E20: NOV | F20: DEZ
B21: Metalurgia | C21: CHESF | D21: 74.39685 | E21: 74.39685 | F21: 74.39685
C22: CPFL | D22: 199.84965 | E22: 199.84965 | F22: 199.84965
C23: AES | D23: 118.27448 | E23: 118.27448 | F23: 118.27448
C24: SPOT | D24: =86.61*0.9075 -> 78.598575 | E24: =86.61*0.9075 -> 78.598575 | F24: =86.61*0.9075 -> 78.598575
B25: Mineração | C25: PRIME | D25: 97.19325 | E25: 97.19325 | F25: 97.19325
C26: Neoenergia | D26: 95.060625 | E26: 95.060625 | F26: 95.060625
B29: Preço Médio R$/MWh | D29: OUT | E29: NOV | F29: DEZ
B30: Metalurgia- ML | D30: =SUMPRODUCT(D13:D15,D22:D24)/SUM(D13:D15) -> 136.032 | E30: =SUMPRODUCT(E13:E15,E22:E24)/SUM(E13:E15) -> 136.032 | F30: =SUMPRODUCT(F13:F15,F22:F24)/SUM(F13:F15) -> 136.032
B31: Mineração - IPUEIRA | D31: =D25 -> 97.19325 | E31: =E25 -> 97.19325 | F31: =F25 -> 97.19325
B32: Mineração - Pedrinhas e Coitez. | D32: =D26 -> 95.060625 | E32: =E26 -> 95.060625 | F32: =F26 -> 95.060625
